Workbook

Sheet 2026 éves
D2: SIM kártya | E2: Éves Felülvizsgálat | F2: Szolgáltató | G2: Január | I2: Február | K2: Március | M2: Április | O2: Május | Q2: Június | S2: Július | U2: Augusztus | W2: Szeptember | Y2: Október | AA2: November | AC2: December
G3: összesen | H3: kp | I3: összesen | J3: kp | K3: összesen | L3: kp | M3: összesen | N3: kp | O3: összesen | P3: kp | Q3: összesen | R3: kp | S3: összesen | T3: kp | U3: összesen | V3: kp | W3: összesen | X3: kp | Y3: összesen | Z3: kp | AA3: összesen | AB3: kp | AC3: összesen | AD3: kp
B4: Államkincstár | C4: =MÁK!A1 -> AP A13610440 | D4: 89430301901300660410 | E4: 2025.01.17 | F4: Telekom | G4: ='202601'!M3 -> 7171251.5 | H4: ='202601'!J3 -> 459515 | I4: ='202602'!M3 -> 7420547 | J4: ='202602'!J3 -> 495690 | K4: ='202603'!M3 -> 8220375 | L4: ='202603'!J3 -> 531410 | M4: ='202604'!M3 -> 410185 | N4: ='202604'!J3 -> 18975
B6: Knorr105 | C6: =Knorr105!A1 -> AP A09111376 | D6: 89430301901301320188 | E6: 2025.08.19 | F6: Telekom | G6: ='202601'!M5 -> 8507316 | H6: ='202601'!J5 -> 7190 | I6: ='202602'!M5 -> 7875677 | J6: ='202602'!J5 -> 0 | K6: ='202603'!M5 -> 8959031 | L6: ='202603'!J5 -> 7760 | M6: ='202604'!M5 -> 504205 | N6: ='202604'!J5 -> 0
B7: Knorr105 | C7: =Knorr105!Q1 -> AP A24010154 | D7: 89430301902202292666 | E7: 2025.06.18 | F7: Telekom | G7: ='202601'!M6 -> 11291268 | H7: ='202601'!J6 -> 4225 | I7: ='202602'!M6 -> 11339936 | J7: ='202602'!J6 -> 17725 | K7: ='202603'!M6 -> 13305803 | L7: ='202603'!J6 -> 10140 | M7: ='202604'!M6 -> 1012005 | N7: ='202604'!J6 -> 1990
B8: Knorr105 | C8: =Knorr105!AG1 -> AP A13609805 | D8: 861075025184672 | E8: 2025.07.23. | F8: Mobil Adat | G8: ='202601'!M7 -> 7283289.5 | H8: ='202601'!J7 -> 0 | I8: ='202602'!M7 -> 7712250 | J8: ='202602'!J7 -> 0 | K8: ='202603'!M7 -> 7748276 | L8: ='202603'!J7 -> 0 | M8: ='202604'!M7 -> 803240 | N8: ='202604'!J7 -> 0
B9: Knorr105 | C9: AP A09110892 | D9: 89430301901300660519 | E9: 2025.07.02. | F9: Telekom | G9: ='202601'!M8 -> 4251199.5 | H9: ='202601'!J8 -> 0 | I9: ='202602'!M8 -> 3650765 | J9: ='202602'!J8 -> 0 | K9: ='202603'!M8 -> 5197181 | L9: ='202603'!J8 -> 5870 | M9: ='202604'!M8 -> 546650 | N9: ='202604'!J8 -> 0
B11: Knorr86 | C11: =Knorr86!A1 -> AP A13607465 | D11: 861075020676789 | E11: 2025.10.29. | F11: Mobil Adat | G11: ='202601'!M10 -> 4985745.5 | H11: ='202601'!J10 -> 29890 | I11: ='202602'!M10 -> 4902145 | J11: ='202602'!J10 -> 37230 | K11: ='202603'!M10 -> 5613404 | L11: ='202603'!J10 -> 43750 | M11: ='202604'!M10 -> 0 | N11: ='202604'!J10 -> 0
B13: Knorr69 | C13: =Knorr69!A1 -> AP A09111377 | D13: 89430301901301321897 | E13: 2025.08.21. | F13: Telekom | G13: ='202601'!M12 -> 7505770.5 | H13: ='202601'!J12 -> 350 | I13: ='202602'!M12 -> 7048430 | J13: ='202602'!J12 -> 0 | K13: ='202603'!M12 -> 8469423 | L13: ='202603'!J12 -> 10615 | M13: ='202604'!M12 -> 335378 | N13: ='202604'!J12 -> 0
B15: KTI | C15: =KTI!A1 -> AP A13607773 | D15: 861075020652764 | E15: 2025.11.03. | F15: Mobil Adat | G15: ='202601'!M14 -> 3588791.5 | H15: ='202601'!J14 -> 491910 | I15: ='202602'!M14 -> 3120005 | J15: ='202602'!J14 -> 322525 | K15: ='202603'!M14 -> 3575864 | L15: ='202603'!J14 -> 364510 | M15: ='202604'!M14 -> 0 | N15: ='202604'!J14 -> 0
B17: Szentkirályi | C17: =Szentkiralyi!A1 -> AP A13611447 | D17: 89430301901301335574 | F17: Telekom | G17: ='202601'!M16 -> 507294.5 | H17: ='202601'!J16 -> 52355 | I17: ='202602'!M16 -> 877923 | J17: ='202602'!J16 -> 64210 | K17: ='202603'!M16 -> 1012079 | L17: ='202603'!J16 -> 82095 | M17: ='202604'!M16 -> 0 | N17: ='202604'!J16 -> 0
B19: RSR | C19: AP A09111370 | D19: 89430301901301322416 | E19: 2025.08.19. | F19: Telekom | G19: ='202601'!M18 -> 3828452.5 | H19: ='202601'!J18 -> 864660 | I19: ='202602'!M18 -> 3408115 | J19: ='202602'!J18 -> 1580415 | K19: ='202603'!M18 -> 3624292 | L19: ='202603'!J18 -> 1134560 | M19: ='202604'!M18 -> 13510 | N19: ='202604'!J18 -> 3350
B20: RSR | C20: AP A13610439 | D20: 89430301901300660584 | E20: 2026.01.27. | F20: Telekom | G20: ='202601'!M19 -> 1542637.5 | H20: ='202601'!J19 -> 115925 | I20: ='202602'!M19 -> 1633064 | J20: ='202602'!J19 -> 841685 | K20: ='202603'!M19 -> 460121 | L20: ='202603'!J19 -> 136215 | M20: ='202604'!M19 -> 0 | N20: ='202604'!J19 -> 0
B21: RSR (Egyéb) | C21: AP A13609679 | D21: 861075020660809 | E21: 45961 | F21: Mobil Adat | G21: ='202601'!M21 -> 866285.5 | H21: ='202601'!J21 -> 343775 | I21: ='202602'!M20 -> 3730025 | J21: ='202602'!J20 -> 1760265 | K21: ='202603'!M20 -> 0 | L21: ='202603'!J20 -> 0 | M21: ='202604'!M20 -> 0 | N21: ='202604'!J20 -> 0
B22: RSR (Egyéb) | C22: AP A09109974 | D22: 861075020660411 | E22: 45958 | F22: Mobil Adat | G22: ='202601'!M22 -> 0 | H22: ='202601'!J22 -> 0 | I22: ='202602'!M21 -> 112060 | J22: ='202602'!J21 -> 34150 | K22: ='202603'!M21 -> 100380 | L22: ='202603'!J21 -> 24640 | M22: ='202604'!M21 -> 0 | N22: ='202604'!J21 -> 0
B24: Egyéb | C24: AP A13608072 | D24: 864403042171471 | E24: 2025.10.28. | F24: Mobil Adat | G24: ='202601'!M23 -> 466823 | H24: ='202601'!J23 -> 28930 | I24: ='202602'!M23 -> 398680 | J24: ='202602'!J23 -> 22860 | K24: ='202603'!M23 -> 0 | L24: ='202603'!J23 -> 0 | M24: ='202604'!M23 -> 185209 | N24: ='202604'!J23 -> 12210
B25: Egyéb | C25: AP A13607772 | D25: 861075024542649 | E25: 2025.10.30. | F25: Mobil Adat | G25: ='202601'!M24 -> 449584 | H25: ='202601'!J24 -> 26565 | I25: ='202602'!M24 -> 270584 | J25: ='202602'!J24 -> 28570 | K25: ='202603'!M24 -> 0 | L25: ='202603'!J24 -> 0 | M25: ='202604'!M24 -> 0 | N25: ='202604'!J24 -> 0
B26: Összesen: | G26: =SUM(G4:G25) -> 62245709 | H26: =SUM(H4:H25) -> 2425290 | I26: =SUM(I4:I25) -> 63500206 | J26: =SUM(J4:J25) -> 5205325 | K26: =SUM(K4:K25) -> 66286229 | L26: =SUM(L4:L25) -> 2351565 | M26: =SUM(M4:M25) -> 3810382 | N26: =SUM(N4:N25) -> 36525 | ... AD26: =SUM(AD4:AD25) -> 0
B28: SELEJT PÉNZTÁRGÉPEK
B30: A24004860 | C30: - | D30: 89430301902006414060 | F30: Telekom | G30: 2024.12.19. selejtezve | I30: szüneteltetve: 2025,05,14
B31: A24004855 | C31: AEE csere nincs bele | D31: 89430301902006411884 | F31: Telekom | I31: szüneteltetve: 2025,05,14
B32: A24004856 | C32: nem kommunikál a Navval | D32: 89430301902006410613 | F32: Telekom | G32: 2024.12.19. selejtezve
B33: A19503259 | C33: hiányzik a fogaskerék | D33: 861311007446874 | F33: Mobil Adat | G33: selejtezve
B34: A13607768 | D34: 861075020653549 | F34: Mobil Adat | G34: 2025.11.hóban selejtezve

Sheet 202604
C2: AP kód | D2: Nyitó zárás | E2: Záró zárás | F2: 0 | G2: 0.05 | H2: 0.18 | I2: 0.27 | J2: kp | K2: bankkártya | L2: bankkártya terminál szerint | M2: Időszak összes | N2: Göngy. forgalom | P2: kp | Q2: bk
B3: Államkincstár | C3: =MÁK!A1 -> AP A13610440 | F3: =MÁK!C160 -> 1100 | G3: =MÁK!D160 -> 207600 | H3: =MÁK!E160 -> 0 | I3: =MÁK!F160 -> 201485 | J3: =MÁK!G160 -> 18975 | K3: =MÁK!H160 -> 391210 | L3: =MÁK!I160 -> 391210 | M3: =SUM(F3:I3) -> 410185 | P3: =J3+#REF! -> #REF! | Q3: =SUM(M3:M3)-P3 -> #REF!
B5: Knorr105 | C5: =Knorr105!A1 -> AP A09111376 | F5: =Knorr105!C$161 -> 1550 | G5: =Knorr105!D$161 -> 502655 | H5: =Knorr105!E$161 -> 0 | I5: =Knorr105!F$161 -> 0 | J5: =Knorr105!G$161 -> 0 | K5: =Knorr105!H$161 -> 504205 | L5: =Knorr105!I$161 -> 504940 | M5: =SUM(F5:I5) -> 504205 | P5: =J5+J6+J7 -> 1990 | Q5: =SUM(M5:M7)-P5 -> 2317460
B6: Knorr105 | C6: =Knorr105!Q1 -> AP A24010154 | F6: =Knorr105!S$161 -> 5390 | G6: =Knorr105!T$161 -> 1006615 | H6: =Knorr105!U$161 -> 0 | I6: =Knorr105!V$161 -> 0 | J6: =Knorr105!W$161 -> 1990 | K6: =Knorr105!X$161 -> 1010015 | L6: =Knorr105!Y$161 -> 1010015 | M6: =SUM(F6:I6) -> 1012005
B7: Knorr105 | C7: =Knorr105!AG1 -> AP A13609805 | F7: =Knorr105!AI$161 -> 3450 | G7: =Knorr105!AJ$161 -> 799790 | H7: =Knorr105!AK$161 -> 0 | I7: =Knorr105!AL$161 -> 0 | J7: =Knorr105!AM$161 -> 0 | K7: =Knorr105!AN$161 -> 803240 | L7: =Knorr105!AO$161 -> 803240 | M7: =SUM(F7:I7) -> 803240
B8: Knorr105 | C8: AP A09110892 | F8: =Knorr105!BK161 -> 219480 | G8: =Knorr105!BL161 -> 327170 | H8: =Knorr105!BM161 -> 0 | I8: =Knorr105!BN161 -> 0 | J8: =Knorr105!BO161 -> 0 | K8: =Knorr105!BP161 -> 546650 | L8: =Knorr105!BQ161 -> 546650 | M8: =SUM(F8:I8) -> 546650
B10: Knorr86 | C10: =Knorr86!A1 -> AP A13607465 | F10: =Knorr86!C159 -> 0 | G10: =Knorr86!D159 -> 0 | H10: =Knorr86!E159 -> 0 | I10: =Knorr86!F159 -> 0 | J10: =Knorr86!G159 -> 0 | K10: =Knorr86!H159 -> 0 | L10: =Knorr86!I159 -> 0 | M10: =SUM(F10:I10) -> 0 | P10: =J10 -> 0 | Q10: =M10-P10 -> 0
B12: Knorr69 | C12: =Knorr69!A1 -> AP A09111377 | F12: =Knorr69!C159 -> 250 | G12: =Knorr69!D159 -> 327308 | H12: =Knorr69!E159 -> 0 | I12: =Knorr69!F159 -> 7820 | J12: =Knorr69!G159 -> 0 | K12: =Knorr69!H159 -> 335378 | L12: =Knorr69!I159 -> 335378 | M12: =SUM(F12:I12) -> 335378 | P12: =J12 -> 0 | Q12: =M12-P12 -> 335378
B14: KTI | C14: =KTI!A1 -> AP A13607773 | F14: =KTI!C159 -> 0 | G14: =KTI!D159 -> 0 | H14: =KTI!E159 -> 0 | I14: =KTI!F159 -> 0 | J14: =KTI!G159 -> 0 | K14: =KTI!H159 -> 0 | L14: =KTI!I159 -> 0 | M14: =SUM(F14:I14) -> 0 | P14: =J14 -> 0 | Q14: =M14-P14 -> 0
B16: Szentkirályi | C16: AP A13611447 | F16: =Szentkiralyi!C159 -> 0 | G16: =Szentkiralyi!D159 -> 0 | H16: =Szentkiralyi!E159 -> 0 | I16: =Szentkiralyi!F159 -> 0 | J16: =Szentkiralyi!G159 -> 0 | K16: =Szentkiralyi!H159 -> 0 | L16: =Szentkiralyi!I159 -> 0 | M16: =SUM(F16:I16) -> 0
B18: RSR | C18: AP A09111370 | F18: =RSR!C161 -> 50 | G18: =RSR!D161 -> 11800 | H18: =RSR!E161 -> 0 | I18: =RSR!F161 -> 1660 | J18: =RSR!G161 -> 3350 | K18: =RSR!H161 -> 10160 | L18: =RSR!I161 -> 10160 | M18: =SUM(F18:I18) -> 13510 | P18: =SUM(J18:J19) -> 3350 | Q18: =SUM(M18:M19)-P18 -> 10160
B19: RSR | C19: AP A13610439 | F19: =RSR!S161 -> 0 | G19: =RSR!T161 -> 0 | H19: =RSR!U161 -> 0 | I19: =RSR!V161 -> 0 | J19: =RSR!W161 -> 0 | K19: =RSR!X161 -> 0 | L19: =RSR!Y161 -> 0 | M19: =SUM(F19:I19) -> 0
B20: RSR | C20: ='Egyéb pénztárgépek'!M1 -> AP A13609679 | F20: =RSR!AI161 -> 0 | G20: =RSR!AJ161 -> 0 | H20: =RSR!AK161 -> 0 | I20: =RSR!AL161 -> 0 | J20: =RSR!AM161 -> 0 | K20: =RSR!AN161 -> 0 | L20: =RSR!AO161 -> 0 | M20: =SUM(F20:I20) -> 0
B21: RSR | C21: ='Egyéb pénztárgépek'!AC1 -> AP A09109974 | F21: =RSR!AY161 -> 0 | G21: =RSR!AZ161 -> 0 | H21: =RSR!BA161 -> 0 | I21: =RSR!BB161 -> 0 | J21: =RSR!BC161 -> 0 | K21: =RSR!BD161 -> 0 | L21: =RSR!BE161 -> 0 | M21: =SUM(F21:I21) -> 0
B23: Egyéb | C23: AP A13608072 | F23: ='Egyéb pénztárgépek'!AT159 -> 1150 | G23: ='Egyéb pénztárgépek'!AU159 -> 162340 | H23: ='Egyéb pénztárgépek'!AV159 -> 0 | I23: ='Egyéb pénztárgépek'!AW159 -> 21719 | J23: ='Egyéb pénztárgépek'!AX159 -> 12210 | K23: ='Egyéb pénztárgépek'!AY159 -> 172999 | L23: ='Egyéb pénztárgépek'!AZ159 -> 172999 | M23: =SUM(F23:I23) -> 185209
B24: Egyéb | C24: AP A13607772 | D24: 2260 | F24: ='Egyéb pénztárgépek'!BJ159 -> 0 | G24: ='Egyéb pénztárgépek'!BK159 -> 0 | H24: ='Egyéb pénztárgépek'!BL159 -> 0 | I24: ='Egyéb pénztárgépek'!BM159 -> 0 | J24: ='Egyéb pénztárgépek'!BN159 -> 0 | K24: ='Egyéb pénztárgépek'!BO159 -> 0 | L24: ='Egyéb pénztárgépek'!BP159 -> 0 | M24: =SUM(F24:I24) -> 0
B27: Összesen: | F27: =SUM(F3:F24) -> 232420 | G27: =SUM(G3:G24) -> 3345278 | H27: =SUM(H3:H24) -> 0 | I27: =SUM(I3:I24) -> 232684 | J27: 1495140 | L27: =SUM(L3:L24) -> 3774592 | M27: =SUM(M3:M24) -> 3810382

Sheet 202603
C2: AP kód | D2: Nyitó zárás | E2: Záró zárás | F2: 0 | G2: 0.05 | H2: 0.18 | I2: 0.27 | J2: kp | K2: bankkártya | L2: bankkártya terminál szerint | M2: Időszak összes | N2: Göngy. forgalom | P2: kp | Q2: bk
B3: Államkincstár | C3: =MÁK!A1 -> AP A13610440 | D3: 1050 | E3: 1072 | F3: =MÁK!C119 -> 23800 | G3: =MÁK!D119 -> 4199840 | H3: =MÁK!E119 -> 0 | I3: =MÁK!F119 -> 3996735 | J3: =MÁK!G119 -> 531410 | K3: =MÁK!H119 -> 7687125 | L3: =MÁK!I119 -> 7687125 | M3: =SUM(F3:I3) -> 8220375 | N3: 235157219 | P3: =J3+#REF! -> #REF! | Q3: =SUM(M3:M3)-P3 -> #REF!
B5: Knorr105 | C5: =Knorr105!A1 -> AP A09111376 | D5: 0470 | E5: 0492 | F5: =Knorr105!C$119 -> 26000 | G5: =Knorr105!D$119 -> 8932881 | H5: =Knorr105!E$119 -> 150 | I5: =Knorr105!F$119 -> 0 | J5: =Knorr105!G$119 -> 7760 | K5: =Knorr105!H$119 -> 8951271 | L5: =Knorr105!I$119 -> 8951271 | M5: =SUM(F5:I5) -> 8959031 | N5: 150445134 | P5: =J5+J6+J7 -> 17900 | Q5: =SUM(M5:M7)-P5 -> 29995210
B6: Knorr105 | C6: =Knorr105!Q1 -> AP A24010154 | D6: 0426 | E6: 0447 | F6: =Knorr105!S$119 -> 73070 | G6: =Knorr105!T$119 -> 13232680 | H6: =Knorr105!U$119 -> 50 | I6: =Knorr105!V$119 -> 3 | J6: =Knorr105!W$119 -> 10140 | K6: =Knorr105!X$119 -> 13295663 | L6: =Knorr105!Y$119 -> 13295663 | M6: =SUM(F6:I6) -> 13305803 | N6: 188928689
B7: Knorr105 | C7: =Knorr105!AG1 -> AP A13609805 | D7: 1281 | E7: 1302 | F7: =Knorr105!AI$119 -> 39830 | G7: =Knorr105!AJ$119 -> 7708396 | H7: =Knorr105!AK$119 -> 50 | I7: =Knorr105!AL$119 -> 0 | J7: =Knorr105!AM$119 -> 0 | K7: =Knorr105!AN$119 -> 7748276 | L7: =Knorr105!AO$119 -> 7748276 | M7: =SUM(F7:I7) -> 7748276 | N7: 319229393
B8: Knorr105 | C8: AP A09110892 | D8: 1031 | E8: 1052 | F8: =Knorr105!BK119 -> 22635 | G8: =Knorr105!BL119 -> 5174496 | H8: =Knorr105!BM119 -> 0 | I8: =Knorr105!BN119 -> 50 | J8: =Knorr105!BO119 -> 5870 | K8: =Knorr105!BP119 -> 5191311 | L8: =Knorr105!BQ119 -> 5177161 | M8: =SUM(F8:I8) -> 5197181 | N8: 179140358
B10: Knorr86 | C10: =Knorr86!A1 -> AP A13607465 | D10: 2315 | E10: 2336 | F10: =Knorr86!C118 -> 41190 | G10: =Knorr86!D118 -> 5365804 | H10: =Knorr86!E118 -> 0 | I10: =Knorr86!F118 -> 206410 | J10: =Knorr86!G118 -> 43750 | K10: =Knorr86!H118 -> 5569654 | L10: =Knorr86!I118 -> 5569654 | M10: =SUM(F10:I10) -> 5613404 | N10: 220258229 | P10: =J10 -> 43750 | Q10: =M10-P10 -> 5569654
B12: Knorr69 | C12: =Knorr69!A1 -> AP A09111377 | D12: 0568 | E12: 0590 | F12: =Knorr69!C118 -> 5000 | G12: =Knorr69!D118 -> 8319343 | H12: =Knorr69!E118 -> 0 | I12: =Knorr69!F118 -> 145080 | J12: =Knorr69!G118 -> 10615 | K12: =Knorr69!H118 -> 8458808 | L12: =Knorr69!I118 -> 8475207 | M12: =SUM(F12:I12) -> 8469423 | N12: 149604290 | P12: =J12 -> 10615 | Q12: =M12-P12 -> 8458808
B14: KTI | C14: =KTI!A1 -> AP A13607773 | D14: 1788 | E14: 1809 | F14: =KTI!C118 -> 15350 | G14: =KTI!D118 -> 3167135 | H14: =KTI!E118 -> 34564 | I14: =KTI!F118 -> 358815 | J14: =KTI!G118 -> 364510 | K14: =KTI!H118 -> 3207124 | L14: =KTI!I118 -> 3207124 | M14: =SUM(F14:I14) -> 3575864 | N14: 213632400 | P14: =J14 -> 364510 | Q14: =M14-P14 -> 3211354
B16: Szentkirályi | C16: AP A13611447 | D16: 0064 | E16: 0077 | F16: =Szentkiralyi!C118 -> 6815 | G16: =Szentkiralyi!D118 -> 898808 | H16: =Szentkiralyi!E118 -> 0 | I16: =Szentkiralyi!F118 -> 106456 | J16: =Szentkiralyi!G118 -> 82095 | K16: =Szentkiralyi!H118 -> 929982 | L16: =Szentkiralyi!I118 -> 929552 | M16: =SUM(F16:I16) -> 1012079 | N16: 6613472
B18: RSR | C18: AP A09111370 | D18: 0593 | E18: 0609 | F18: =RSR!C120 -> 12050 | G18: =RSR!D120 -> 2689383 | H18: =RSR!E120 -> 400790 | I18: =RSR!F120 -> 522069 | J18: =RSR!G120 -> 1134560 | K18: =RSR!H120 -> 2549719 | L18: =RSR!I120 -> 0 | M18: =SUM(F18:I18) -> 3624292 | N18: 113059608 | P18: =SUM(J18:J19) -> 1270775 | Q18: =SUM(M18:M19)-P18 -> 2813638
B19: RSR | C19: AP A13610439 | D19: 0375 | E19: 0379 | F19: =RSR!S120 -> 12500 | G19: =RSR!T120 -> 16010 | H19: =RSR!U120 -> 28550 | I19: =RSR!V120 -> 403061 | J19: =RSR!W120 -> 136215 | K19: =RSR!X120 -> 323912 | L19: =RSR!Y120 -> 335180 | M19: =SUM(F19:I19) -> 460121 | N19: 46375797
B20: RSR | C20: ='Egyéb pénztárgépek'!M1 -> AP A13609679 | D20: 1035 | E20: 1039 | F20: =RSR!AI120 -> 0 | G20: =RSR!AJ120 -> 0 | H20: =RSR!AK120 -> 0 | I20: =RSR!AL120 -> 0 | J20: =RSR!AM120 -> 0 | K20: =RSR!AN120 -> 0 | L20: =RSR!AO120 -> 0 | M20: =SUM(F20:I20) -> 0 | N20: 277375359
B21: RSR | C21: ='Egyéb pénztárgépek'!AC1 -> AP A09109974 | D21: 1453 | E21: 1464 | F21: =RSR!AY120 -> 200 | G21: =RSR!AZ120 -> 80120 | H21: =RSR!BA120 -> 12030 | I21: =RSR!BB120 -> 8030 | J21: =RSR!BC120 -> 24640 | K21: =RSR!BD120 -> 75740 | L21: =RSR!BE120 -> 73000 | M21: =SUM(F21:I21) -> 100380 | N21: 220449392
B23: Egyéb | C23: AP A13608072 | D23: 1680 | E23: 1689 | F23: ='Egyéb pénztárgépek'!AT117 -> 0 | G23: ='Egyéb pénztárgépek'!AU117 -> 0 | H23: ='Egyéb pénztárgépek'!AV117 -> 0 | I23: ='Egyéb pénztárgépek'!AW117 -> 0 | J23: ='Egyéb pénztárgépek'!AX117 -> 0 | K23: ='Egyéb pénztárgépek'!AY117 -> 0 | L23: ='Egyéb pénztárgépek'!AZ117 -> 0 | M23: =SUM(F23:I23) -> 0 | N23: 265799692
B24: Egyéb | C24: AP A13607772 | D24: 2256 | E24: 2259 | F24: ='Egyéb pénztárgépek'!BJ117 -> 0 | G24: ='Egyéb pénztárgépek'!BK117 -> 0 | H24: ='Egyéb pénztárgépek'!BL117 -> 0 | I24: ='Egyéb pénztárgépek'!BM117 -> 0 | J24: ='Egyéb pénztárgépek'!BN117 -> 0 | K24: ='Egyéb pénztárgépek'!BO117 -> 0 | L24: ='Egyéb pénztárgépek'!BP117 -> 0 | M24: =SUM(F24:I24) -> 0 | N24: 285033762
B27: Összesen: | F27: =SUM(F3:F24) -> 278440 | G27: =SUM(G3:G24) -> 59784896 | H27: =SUM(H3:H24) -> 476184 | I27: =SUM(I3:I24) -> 5746709 | J27: 1495140 | L27: =SUM(L3:L24) -> 53200611 | M27: =SUM(M3:M24) -> 66286229

Sheet 202602
C2: AP kód | D2: Nyitó zárás | E2: Záró zárás | F2: 0 | G2: 0.05 | H2: 0.18 | I2: 0.27 | J2: kp | K2: bankkártya | L2: bankkártya terminál szerint | M2: Időszak összes | N2: Göngy. forgalom | P2: kp | Q2: bk
B3: Államkincstár | C3: =MÁK!A1 -> AP A13610440 | D3: 1030 | E3: 1049 | F3: =MÁK!C76 -> 19240 | G3: =MÁK!D76 -> 4535249 | H3: =MÁK!E76 -> 3894 | I3: =MÁK!F76 -> 2862164 | J3: =MÁK!G76 -> 495690 | K3: =MÁK!H76 -> 6920105 | L3: =MÁK!I76 -> 6920105 | M3: =SUM(F3:I3) -> 7420547 | N3: 226936844 | P3: =J3+#REF! -> #REF! | Q3: =SUM(M3:M3)-P3 -> #REF!
B5: Knorr105 | C5: =Knorr105!A1 -> AP A09111376 | D5: 0449 | E5: 0469 | F5: =Knorr105!C$76 -> 15290 | G5: =Knorr105!D$76 -> 7857997 | H5: =Knorr105!E$76 -> 50 | I5: =Knorr105!F$76 -> 2340 | J5: =Knorr105!G$76 -> 0 | K5: =Knorr105!H$76 -> 7875677 | L5: =Knorr105!I$76 -> 7875677 | M5: =SUM(F5:I5) -> 7875677 | N5: 141486103 | P5: =J5+J6+J7 -> 17725 | Q5: =SUM(M5:M7)-P5 -> 26910138
B6: Knorr105 | C6: =Knorr105!Q1 -> AP A24010154 | D6: 0406 | E6: 0425 | F6: =Knorr105!S$76 -> 60410 | G6: =Knorr105!T$76 -> 11279526 | H6: =Knorr105!U$76 -> 0 | I6: =Knorr105!V$76 -> 0 | J6: =Knorr105!W$76 -> 17725 | K6: =Knorr105!X$76 -> 11322211 | L6: =Knorr105!Y$76 -> 11322211 | M6: =SUM(F6:I6) -> 11339936 | N6: 175622886
B7: Knorr105 | C7: =Knorr105!AG1 -> AP A13609805 | D7: 1260 | E7: 1280 | F7: =Knorr105!AI$76 -> 34330 | G7: =Knorr105!AJ$76 -> 7673400 | H7: =Knorr105!AK$76 -> 0 | I7: =Knorr105!AL$76 -> 4520 | J7: =Knorr105!AM$76 -> 0 | K7: =Knorr105!AN$76 -> 7712250 | L7: =Knorr105!AO$76 -> 7712250 | M7: =SUM(F7:I7) -> 7712250 | N7: 311481117
B8: Knorr105 | C8: AP A09110892 | D8: 1011 | E8: 1030 | F8: =Knorr105!BK76 -> 13550 | G8: =Knorr105!BL76 -> 3637165 | H8: =Knorr105!BM76 -> 50 | I8: =Knorr105!BN76 -> 0 | J8: =Knorr105!BO76 -> 0 | K8: =Knorr105!BP76 -> 3650765 | L8: =Knorr105!BQ76 -> 3650765 | M8: =SUM(F8:I8) -> 3650765 | N8: 173943177
B10: Knorr86 | C10: =Knorr86!A1 -> AP A13607465 | D10: 2295 | E10: 2314 | F10: =Knorr86!C75 -> 28620 | G10: =Knorr86!D75 -> 4727400 | H10: =Knorr86!E75 -> 0 | I10: =Knorr86!F75 -> 146125 | J10: =Knorr86!G75 -> 37230 | K10: =Knorr86!H75 -> 4864915 | L10: =Knorr86!I75 -> 4864915 | M10: =SUM(F10:I10) -> 4902145 | N10: 214644825 | P10: =J10 -> 37230 | Q10: =M10-P10 -> 4864915
B12: Knorr69 | C12: =Knorr69!A1 -> AP A09111377 | D12: 0548 | E12: 0567 | F12: =Knorr69!C75 -> 4505 | G12: =Knorr69!D75 -> 6881361 | H12: =Knorr69!E75 -> 0 | I12: =Knorr69!F75 -> 162564 | J12: =Knorr69!G75 -> 0 | K12: =Knorr69!H75 -> 7049220 | L12: =Knorr69!I75 -> 7048430 | M12: =SUM(F12:I12) -> 7048430 | N12: 141134867 | P12: =J12 -> 0 | Q12: =M12-P12 -> 7048430
B14: KTI | C14: =KTI!A1 -> AP A13607773 | D14: 1768 | E14: 1787 | F14: =KTI!C75 -> 5700 | G14: =KTI!D75 -> 2761430 | H14: =KTI!E75 -> 25465 | I14: =KTI!F75 -> 327410 | J14: =KTI!G75 -> 322525 | K14: =KTI!H75 -> 2797480 | L14: =KTI!I75 -> 2797480 | M14: =SUM(F14:I14) -> 3120005 | N14: 210056536 | P14: =J14 -> 322525 | Q14: =M14-P14 -> 2797480
B16: Szentkirályi | C16: AP A13611447 | D16: 0050 | E16: 0062 | F16: =Szentkiralyi!C75 -> 6670 | G16: =Szentkiralyi!D75 -> 756232 | H16: =Szentkiralyi!E75 -> 10360 | I16: =Szentkiralyi!F75 -> 104661 | J16: =Szentkiralyi!G75 -> 64210 | K16: =Szentkiralyi!H75 -> 813713 | L16: =Szentkiralyi!I75 -> 813713 | M16: =SUM(F16:I16) -> 877923 | N16: 5601393
B18: RSR | C18: AP A09111370 | D18: 0582 | E18: 0592 | F18: =RSR!C75 -> 32700 | G18: =RSR!D75 -> 1977405 | H18: =RSR!E75 -> 117550 | I18: =RSR!F75 -> 1280460 | J18: =RSR!G75 -> 1580415 | K18: =RSR!H75 -> 1853719 | L18: =RSR!I75 -> 1848229 | M18: =SUM(F18:I18) -> 3408115 | N18: 109435316 | P18: =SUM(J18:J19) -> 2422100 | Q18: =SUM(M18:M19)-P18 -> 2619079
B19: RSR | C19: AP A13610439 | D19: 0368 | E19: 0373 | F19: =RSR!S75 -> 35690 | G19: =RSR!T75 -> 615963 | H19: =RSR!U75 -> 67370 | I19: =RSR!V75 -> 914041 | J19: =RSR!W75 -> 841685 | K19: =RSR!X75 -> 821379 | L19: =RSR!Y75 -> 817167 | M19: =SUM(F19:I19) -> 1633064 | N19: 45915676
B20: RSR | C20: ='Egyéb pénztárgépek'!M1 -> AP A13609679 | D20: 1020 | E20: 1033 | F20: =RSR!AI75 -> 30720 | G20: =RSR!AJ75 -> 1579482 | H20: =RSR!AK75 -> 211985 | I20: =RSR!AL75 -> 1907838 | J20: =RSR!AM75 -> 1760265 | K20: =RSR!AN75 -> 2153995 | L20: =RSR!AO75 -> 1732617 | M20: =SUM(F20:I20) -> 3730025 | N20: 277375359
B21: RSR | C21: ='Egyéb pénztárgépek'!AC1 -> AP A09109974 | D21: 1448 | E21: 1452 | F21: =RSR!AY75 -> 600 | G21: =RSR!AZ75 -> 91480 | H21: =RSR!BA75 -> 2520 | I21: =RSR!BB75 -> 17460 | J21: =RSR!BC75 -> 34150 | K21: =RSR!BD75 -> 71910 | L21: =RSR!BE75 -> 73990 | M21: =SUM(F21:I21) -> 112060 | N21: 220349012
B23: Egyéb | C23: AP A13608072 | D23: 1673 | E23: 1680 | F23: ='Egyéb pénztárgépek'!AT78 -> 6950 | G23: ='Egyéb pénztárgépek'!AU78 -> 357344 | H23: ='Egyéb pénztárgépek'!AV78 -> 0 | I23: ='Egyéb pénztárgépek'!AW78 -> 34386 | J23: ='Egyéb pénztárgépek'!AX78 -> 22860 | K23: ='Egyéb pénztárgépek'!AY78 -> 286919 | L23: ='Egyéb pénztárgépek'!AZ78 -> 286918 | M23: =SUM(F23:I23) -> 398680 | N23: 265252089
B24: Egyéb | C24: AP A13607772 | D24: 2250 | E24: 2255 | F24: ='Egyéb pénztárgépek'!BJ79 -> 2261 | G24: ='Egyéb pénztárgépek'!BK79 -> 245833 | H24: ='Egyéb pénztárgépek'!BL79 -> 0 | I24: ='Egyéb pénztárgépek'!BM79 -> 22490 | J24: ='Egyéb pénztárgépek'!BN79 -> 28570 | K24: ='Egyéb pénztárgépek'!BO79 -> 242014 | L24: ='Egyéb pénztárgépek'!BP79 -> 242014 | M24: =SUM(F24:I24) -> 270584 | N24: 284799562
B27: Összesen: | F27: =SUM(F3:F24) -> 297236 | G27: =SUM(G3:G24) -> 54977267 | H27: =SUM(H3:H24) -> 439244 | I27: =SUM(I3:I24) -> 7786459 | J27: 1495140 | L27: =SUM(L3:L24) -> 58006481 | M27: =SUM(M3:M24) -> 63500206

Sheet 202601
C2: AP kód | D2: Nyitó zárás | E2: Záró zárás | F2: 0 | G2: 0.05 | H2: 0.18 | I2: 0.27 | J2: kp | K2: bankkártya | L2: bankkártya terminál szerint | M2: Időszak összes | N2: Göngy. forgalom | P2: kp | Q2: bk
B3: Államkincstár | C3: =MÁK!A1 -> AP A13610440 | D3: 1009 | E3: 1029 | F3: =MÁK!C35 -> 17250 | G3: =MÁK!D35 -> 4328426 | H3: =MÁK!E35 -> 0.18 | I3: =MÁK!F35 -> 2825575.3 | J3: =MÁK!G35 -> 459515 | K3: =MÁK!H35 -> 6705640 | L3: =MÁK!I35 -> 6422478 | M3: =SUM(F3:I3) -> 7171251.5 | N3: 219216297 | P3: =J3+#REF! -> #REF! | Q3: =SUM(M3:M3)-P3 -> #REF!
B5: Knorr105 | C5: =Knorr105!A1 -> AP A09111376 | D5: 0428 | E5: 0448 | F5: =Knorr105!C$35 -> 19250 | G5: =Knorr105!D$35 -> 8487866 | H5: =Knorr105!E$35 -> 200 | I5: =Knorr105!F$35 -> 0 | J5: =Knorr105!G$35 -> 7190 | K5: =Knorr105!H$35 -> 8500126 | L5: =Knorr105!I$35 -> 8131173 | M5: =SUM(F5:I5) -> 8507316 | N5: 133610426 | P5: =J5+J6+J7 -> 11415 | Q5: =SUM(M5:M7)-P5 -> 27070459
B6: Knorr105 | C6: =Knorr105!Q1 -> AP A24010154 | D6: 0384 | E6: 0405 | F6: =Knorr105!S$35 -> 57675 | G6: =Knorr105!T$35 -> 11233593 | H6: =Knorr105!U$35 -> 0.18 | I6: =Knorr105!V$35 -> 0.27 | J6: =Knorr105!W$35 -> 4225 | K6: =Knorr105!X$35 -> 11287043 | L6: =Knorr105!Y$35 -> 11287043 | M6: =SUM(F6:I6) -> 11291268 | N6: 164839238
B7: Knorr105 | C7: =Knorr105!AG1 -> AP A13609805 | D7: 1239 | E7: 1259 | F7: =Knorr105!AI$35 -> 33940 | G7: =Knorr105!AJ$35 -> 7249299 | H7: =Knorr105!AK$35 -> 0.18 | I7: =Knorr105!AL$35 -> 50.27 | J7: =Knorr105!AM$35 -> 0 | K7: =Knorr105!AN$35 -> 7283289 | L7: =Knorr105!AO$35 -> 7283289 | M7: =SUM(F7:I7) -> 7283289.5 | N7: 303768867
B8: Knorr105 | C8: AP A09110892 | D8: 0990 | E8: 1010 | F8: =Knorr105!BK35 -> 21581 | G8: =Knorr105!BL35 -> 4229138 | H8: =Knorr105!BM35 -> 380.18 | I8: =Knorr105!BN35 -> 100.27 | J8: =Knorr105!BO35 -> 0 | K8: =Knorr105!BP35 -> 4250747 | L8: =Knorr105!BQ35 -> 4251651 | M8: =SUM(F8:I8) -> 4251199.5 | N8: 170292412
B10: Knorr86 | C10: =Knorr86!A1 -> AP A13607465 | D10: 2274 | E10: 2294 | F10: =Knorr86!C34 -> 26950 | G10: =Knorr86!D34 -> 4767430 | H10: =Knorr86!E34 -> 0.18 | I10: =Knorr86!F34 -> 191365.27 | J10: =Knorr86!G34 -> 29890 | K10: =Knorr86!H34 -> 4955855 | L10: =Knorr86!I34 -> 4955855 | M10: =SUM(F10:I10) -> 4985745.5 | N10: 209742680 | P10: =J10 -> 29890 | Q10: =M10-P10 -> 4955855.5
B12: Knorr69 | C12: =Knorr69!A1 -> AP A09111377 | D12: 527 | E12: 547 | F12: =Knorr69!C34 -> 3850 | G12: =Knorr69!D34 -> 7303830 | H12: =Knorr69!E34 -> 0.18 | I12: =Knorr69!F34 -> 198090.27 | J12: =Knorr69!G34 -> 350 | K12: =Knorr69!H34 -> 7503330 | L12: =Knorr69!I34 -> 7505420 | M12: =SUM(F12:I12) -> 7505770.5 | N12: 134086437 | P12: =J12 -> 350 | Q12: =M12-P12 -> 7505420.5
B14: KTI | C14: =KTI!A1 -> AP A13607773 | D14: 1747 | E14: 1767 | F14: =KTI!C34 -> 6100 | G14: =KTI!D34 -> 3164628 | H14: =KTI!E34 -> 71322.18 | I14: =KTI!F34 -> 346741.27 | J14: =KTI!G34 -> 491910 | K14: =KTI!H34 -> 3095470 | L14: =KTI!I34 -> 2979140 | M14: =SUM(F14:I14) -> 3588791.5 | N14: 206936531 | P14: =J14 -> 491910 | Q14: =M14-P14 -> 3096881.5
B16: Szentkirályi | C16: AP A13611447 | D16: 0041 | E16: 0049 | F16: =Szentkiralyi!C34 -> 4505 | G16: =Szentkiralyi!D34 -> 442943.05 | H16: =Szentkiralyi!E34 -> 360.18 | I16: =Szentkiralyi!F34 -> 59486.27 | J16: =Szentkiralyi!G34 -> 52355 | K16: =Szentkiralyi!H34 -> 454939 | L16: =Szentkiralyi!I34 -> 451932 | M16: =SUM(F16:I16) -> 507294.5 | N16: 4723470
B18: RSR | C18: AP A09111370 | D18: 0573 | E18: 0581 | F18: =RSR!C34 -> 4396 | G18: =RSR!D34 -> 1079710.1 | H18: =RSR!E34 -> 96790.18 | I18: =RSR!F34 -> 2647556.3 | J18: =RSR!G34 -> 864660 | K18: =RSR!H34 -> 1366490 | L18: =RSR!I34 -> 1372103 | M18: =SUM(F18:I18) -> 3828452.5 | N18: 106027201 | P18: =SUM(J18:J19) -> 980585 | Q18: =SUM(M18:M19)-P18 -> 4390505
B19: RSR | C19: AP A13610439 | D19: 0363 | E19: 0367 | F19: =RSR!S34 -> 550 | G19: =RSR!T34 -> 1494187.1 | H19: =RSR!U34 -> 0.18 | I19: =RSR!V34 -> 47900.27 | J19: =RSR!W34 -> 115925 | K19: =RSR!X34 -> 285015 | L19: =RSR!Y34 -> 271983 | M19: =SUM(F19:I19) -> 1542637.5 | N19: 44282612
B21: Egyéb (RSR) | C21: ='Egyéb pénztárgépek'!M1 -> AP A13609679 | D21: 1016 | E21: 1019 | F21: =RSR!AI36 -> 11065 | G21: =RSR!AJ36 -> 589720.05 | H21: =RSR!AK36 -> 0.18 | I21: =RSR!AL36 -> 265500.27 | J21: =RSR!AM36 -> 343775 | K21: =RSR!AN36 -> 522510 | L21: =RSR!AO36 -> 522510 | M21: =SUM(F21:I21) -> 866285.5 | N21: 273645334
B22: Egyéb (RSR) | C22: ='Egyéb pénztárgépek'!AC1 -> AP A09109974 | D22: 1447 | E22: 1447 | F22: ='Egyéb pénztárgépek'!AD36 -> 0 | G22: ='Egyéb pénztárgépek'!AE36 -> 0 | H22: ='Egyéb pénztárgépek'!AF36 -> 0 | I22: ='Egyéb pénztárgépek'!AG36 -> 0 | J22: ='Egyéb pénztárgépek'!AH36 -> 0 | K22: ='Egyéb pénztárgépek'!AI36 -> 0 | L22: ='Egyéb pénztárgépek'!AJ36 -> 0 | M22: =SUM(F22:I22) -> 0 | N22: 220236952
B23: Egyéb | C23: AP A13608072 | D23: 1666 | E23: 1672 | F23: ='Egyéb pénztárgépek'!AT37 -> 4075 | G23: ='Egyéb pénztárgépek'!AU37 -> 428902 | H23: ='Egyéb pénztárgépek'!AV37 -> 15638 | I23: ='Egyéb pénztárgépek'!AW37 -> 18208 | J23: ='Egyéb pénztárgépek'!AX37 -> 28930 | K23: ='Egyéb pénztárgépek'!AY37 -> 360622 | L23: ='Egyéb pénztárgépek'!AZ37 -> 437893 | M23: =SUM(F23:I23) -> 466823 | N23: 264853409
B24: Egyéb | C24: AP A13607772 | D24: 2243 | E24: 2249 | F24: ='Egyéb pénztárgépek'!BJ36 -> 3850 | G24: ='Egyéb pénztárgépek'!BK36 -> 400331 | H24: ='Egyéb pénztárgépek'!BL36 -> 0 | I24: ='Egyéb pénztárgépek'!BM36 -> 45403 | J24: ='Egyéb pénztárgépek'!BN36 -> 26565 | K24: ='Egyéb pénztárgépek'!BO36 -> 423016 | L24: ='Egyéb pénztárgépek'!BP36 -> 334776 | M24: =SUM(F24:I24) -> 449584 | N24: 284528978
B27: Összesen: | F27: =SUM(F3:F24) -> 215037 | G27: =SUM(G3:G24) -> 55200003 | H27: =SUM(H3:H25) -> 184691.98 | I27: =SUM(I3:I26) -> 6645977 | J27: =SUM(J3:J26) -> 2425290 | L27: =SUM(L3:L24) -> 56207246 | M27: =SUM(M3:M24) -> 62245709

Sheet MÁK
A1: AP A13610440 | B1: Novohost | C1: 0 | D1: 0.05 | E1: 0.18 | F1: 0.27 | G1: készpénz | H1: kártya | I1: terminál sz. bankkártya | J1: zárás sorszám | K1: göngyölt e. | L1: időszaki össz: | M1: EUR | N1: jegyzőkönyv | P1: Novohost
A2: Január | P2: ='[1]2026 január'!B1 -> Novohost | Q2: ='[1]2026 január'!G1 -> Tartalék kiadás | R2: ='[1]2026 január'!W1 -> Kivét | S2: Eredmény | V2: ='[1]2026 január'!S1 -> Pénztár nyitó | W2: ='[1]2026 január'!T1 -> novo kp bevétel | X2: ='[1]2026 január'!U1 -> Egyéb bevétel | Y2: ='[1]2026 január'!V1 -> Költött | Z2: ='[1]2026 január'!W1 -> Kivét | AA2: ='[1]2026 január'!X1 -> Eltérés | AB2: ='[1]2026 január'!Y1 -> Záró | AC2: ='[1]2026 január'!Z1 -> Megjegyzések | ... AG2: ='[1]2026 január'!AD1 -> 0
A3: 46023 | P3: =IF('[1]2026 január'!B$2=0, "", '[1]2026 január'!B$2 ) | Q3: =IF(OR('[1]2026 január'!G2=0, ISBLANK('[1]2026 január'!G2)), "", '[1]2026 január'!G2 ) | R3: ='[1]2026 január'!W2 -> 0 | S3: =P3-Q3-R3-G3-H3 -> #VALUE! | V3: =IF('[1]2026 január'!S2=0, "", '[1]2026 január'!S2 ) | W3: =IF('[1]2026 január'!T2=0, "", '[1]2026 január'!T2 ) | X3: =IF('[1]2026 január'!U2=0, "", '[1]2026 január'!U2 ) | Y3: =IF('[1]2026 január'!V2=0, "", '[1]2026 január'!V2 ) | Z3: =IF('[1]2026 január'!W2=0, "", '[1]2026 január'!W2 ) | AA3: =IF('[1]2026 január'!X2=0, "", '[1]2026 január'!X2 ) | AB3: =IF('[1]2026 január'!Y2=0, "", '[1]2026 január'!Y2 ) | AC3: =IF('[1]2026 január'!Z2=0, "", '[1]2026 január'!Z2 ) | AD3: =IF('[1]2026 január'!AA2=0, "", '[1]2026 január'!AA2 ) | AE3: =IF('[1]2026 január'!AB$2=0, "", '[1]2026 január'!AB$2 ) | AF3: =IF('[1]2026 január'!AC$2=0, "", '[1]2026 január'!AC$2 ) | AG3: =IF('[1]2026 január'!AD$2=0, "", '[1]2026 január'!AD$2 ) | AH3: =IF('[1]2026 január'!AE2=0, "", '[1]2026 január'!AE2 ) | AI3: =IF('[1]2026 január'!AF2=0, "", '[1]2026 január'!AF2 ) | AJ3: =IF('[1]2026 január'!AG2=0, "", '[1]2026 január'!AG2 ) | AK3: =IF('[1]2026 január'!AH2=0, "", '[1]2026 január'!AH2 )
A4: 46024 | P4: =IF('[1]2026 január'!B$3=0, "", '[1]2026 január'!B$3 ) | Q4: =IF(OR('[1]2026 január'!G3=0, ISBLANK('[1]2026 január'!G3)), "", '[1]2026 január'!G3 ) | R4: ='[1]2026 január'!W3 -> 0 | V4: =IF('[1]2026 január'!S3=0, "", '[1]2026 január'!S3 ) | W4: =IF('[1]2026 január'!T3=0, "", '[1]2026 január'!T3 ) | X4: =IF('[1]2026 január'!U3=0, "", '[1]2026 január'!U3 ) | Y4: =IF('[1]2026 január'!V3=0, "", '[1]2026 január'!V3 ) | Z4: =IF('[1]2026 január'!W3=0, "", '[1]2026 január'!W3 ) | AA4: =IF('[1]2026 január'!X3=0, "", '[1]2026 január'!X3 ) | AB4: =IF('[1]2026 január'!Y3=0, "", '[1]2026 január'!Y3 ) | AC4: =IF('[1]2026 január'!Z3=0, "", '[1]2026 január'!Z3 ) | AD4: =IF('[1]2026 január'!AA3=0, "", '[1]2026 január'!AA3 ) | AE4: =IF('[1]2026 január'!AB$3=0, "", '[1]2026 január'!AB$3 ) | AF4: =IF('[1]2026 január'!AC$3=0, "", '[1]2026 január'!AC$3 ) | AG4: =IF('[1]2026 január'!AD$3=0, "", '[1]2026 január'!AD$3 ) | AH4: =IF('[1]2026 január'!AE3=0, "", '[1]2026 január'!AE3 ) | AI4: =IF('[1]2026 január'!AF3=0, "", '[1]2026 január'!AF3 ) | AJ4: =IF('[1]2026 január'!AG3=0, "", '[1]2026 január'!AG3 ) | AK4: =IF('[1]2026 január'!AH3=0, "", '[1]2026 január'!AH3 )
A5: 46025 | P5: =IF('[1]2026 január'!B$4=0, "", '[1]2026 január'!B$4 ) | Q5: =IF(OR('[1]2026 január'!G4=0, ISBLANK('[1]2026 január'!G4)), "", '[1]2026 január'!G4 ) | R5: ='[1]2026 január'!W4 -> 0 | V5: =IF('[1]2026 január'!S4=0, "", '[1]2026 január'!S4 ) | W5: =IF('[1]2026 január'!T4=0, "", '[1]2026 január'!T4 ) | X5: =IF('[1]2026 január'!U4=0, "", '[1]2026 január'!U4 ) | Y5: =IF('[1]2026 január'!V4=0, "", '[1]2026 január'!V4 ) | Z5: =IF('[1]2026 január'!W4=0, "", '[1]2026 január'!W4 ) | AA5: =IF('[1]2026 január'!X4=0, "", '[1]2026 január'!X4 ) | AB5: =IF('[1]2026 január'!Y4=0, "", '[1]2026 január'!Y4 ) | AC5: =IF('[1]2026 január'!Z4=0, "", '[1]2026 január'!Z4 ) | AD5: =IF('[1]2026 január'!AA4=0, "", '[1]2026 január'!AA4 ) | AE5: =IF('[1]2026 január'!AB$4=0, "", '[1]2026 január'!AB$4 ) | AF5: =IF('[1]2026 január'!AC$4=0, "", '[1]2026 január'!AC$4 ) | AG5: =IF('[1]2026 január'!AD$4=0, "", '[1]2026 január'!AD$4 ) | AH5: =IF('[1]2026 január'!AE4=0, "", '[1]2026 január'!AE4 ) | AI5: =IF('[1]2026 január'!AF4=0, "", '[1]2026 január'!AF4 ) | AJ5: =IF('[1]2026 január'!AG4=0, "", '[1]2026 január'!AG4 ) | AK5: =IF('[1]2026 január'!AH4=0, "", '[1]2026 január'!AH4 )
A6: 46026
A7: 46027 | C7: 1150 | D7: 164389 | F7: 177841 | G7: 33775 | H7: 309605 | I7: 314305 | J7: 1009 | K7: 212688426 | P7: =IF('[1]2026 január'!B$5=0, "", '[1]2026 január'!B$5 ) | Q7: =IF(OR('[1]2026 január'!G5=0, ISBLANK('[1]2026 január'!G5)), "", '[1]2026 január'!G5 ) | R7: ='[1]2026 január'!W5 -> 0 | V7: =IF('[1]2026 január'!S5=0, "", '[1]2026 január'!S5 ) | W7: =IF('[1]2026 január'!T5=0, "", '[1]2026 január'!T5 ) | X7: =IF('[1]2026 január'!U5=0, "", '[1]2026 január'!U5 ) | Y7: =IF('[1]2026 január'!V5=0, "", '[1]2026 január'!V5 ) | Z7: =IF('[1]2026 január'!W5=0, "", '[1]2026 január'!W5 ) | AA7: =IF('[1]2026 január'!X5=0, "", '[1]2026 január'!X5 ) | AB7: =IF('[1]2026 január'!Y5=0, "", '[1]2026 január'!Y5 ) | AC7: =IF('[1]2026 január'!Z5=0, "", '[1]2026 január'!Z5 ) | AD7: =IF('[1]2026 január'!AA5=0, "", '[1]2026 január'!AA5 ) | AE7: =IF('[1]2026 január'!AB$5=0, "", '[1]2026 január'!AB$5 ) | AF7: =IF('[1]2026 január'!AC$5=0, "", '[1]2026 január'!AC$5 ) | AG7: =IF('[1]2026 január'!AD$5=0, "", '[1]2026 január'!AD$5 ) | AH7: =IF('[1]2026 január'!AE5=0, "", '[1]2026 január'!AE5 ) | AI7: =IF('[1]2026 január'!AF5=0, "", '[1]2026 január'!AF5 ) | AJ7: =IF('[1]2026 január'!AG5=0, "", '[1]2026 január'!AG5 ) | AK7: =IF('[1]2026 január'!AH5=0, "", '[1]2026 január'!AH5 )
A8: 46027 | B8: 366030 | F8: 4700 | H8: 4700 | J8: 1010 | K8: 212693126 | P8: =IF('[1]2026 január'!B$6=0, "", '[1]2026 január'!B$6 ) -> 348080 | Q8: =IF(OR('[1]2026 január'!G6=0, ISBLANK('[1]2026 január'!G6)), "", '[1]2026 január'!G6 ) | R8: ='[1]2026 január'!W6 -> 0 | V8: =IF('[1]2026 január'!S6=0, "", '[1]2026 január'!S6 ) -> 119577 | W8: =IF('[1]2026 január'!T6=0, "", '[1]2026 január'!T6 ) -> 33775 | X8: =IF('[1]2026 január'!U6=0, "", '[1]2026 január'!U6 ) | Y8: =IF('[1]2026 január'!V6=0, "", '[1]2026 január'!V6 ) | Z8: =IF('[1]2026 január'!W6=0, "", '[1]2026 január'!W6 ) | AA8: =IF('[1]2026 január'!X6=0, "", '[1]2026 január'!X6 ) | AB8: =IF('[1]2026 január'!Y6=0, "", '[1]2026 január'!Y6 ) -> 153352 | AC8: =IF('[1]2026 január'!Z6=0, "", '[1]2026 január'!Z6 ) | AD8: =IF('[1]2026 január'!AA6=0, "", '[1]2026 január'!AA6 ) | AE8: =IF('[1]2026 január'!AB$6=0, "", '[1]2026 január'!AB$6 ) | AF8: =IF('[1]2026 január'!AC$6=0, "", '[1]2026 január'!AC$6 ) | AG8: =IF('[1]2026 január'!AD$6=0, "", '[1]2026 január'!AD$6 ) | AH8: =IF('[1]2026 január'!AE6=0, "", '[1]2026 január'!AE6 ) | AI8: =IF('[1]2026 január'!AF6=0, "", '[1]2026 január'!AF6 ) | AJ8: =IF('[1]2026 január'!AG6=0, "", '[1]2026 január'!AG6 ) | AK8: =IF('[1]2026 január'!AH6=0, "", '[1]2026 január'!AH6 )
A9: 46028 | B9: 412300 | C9: 750 | D9: 242410 | F9: 199650 | G9: 16720 | H9: 426090 | I9: 426090 | J9: 1011 | K9: 213135936 | P9: =IF('[1]2026 január'!B$7=0, "", '[1]2026 január'!B$7 ) -> 402810 | Q9: =IF(OR('[1]2026 január'!G7=0, ISBLANK('[1]2026 január'!G7)), "", '[1]2026 január'!G7 ) | R9: ='[1]2026 január'!W7 -> 0 | V9: =IF('[1]2026 január'!S7=0, "", '[1]2026 január'!S7 ) -> 153352 | W9: =IF('[1]2026 január'!T7=0, "", '[1]2026 január'!T7 ) -> -23280 | X9: =IF('[1]2026 január'!U7=0, "", '[1]2026 január'!U7 ) -> 44985 | Y9: =IF('[1]2026 január'!V7=0, "", '[1]2026 január'!V7 ) -> 3600 | Z9: =IF('[1]2026 január'!W7=0, "", '[1]2026 január'!W7 ) | AA9: =IF('[1]2026 január'!X7=0, "", '[1]2026 január'!X7 ) | AB9: =IF('[1]2026 január'!Y7=0, "", '[1]2026 január'!Y7 ) -> 171457 | AC9: =IF('[1]2026 január'!Z7=0, "", '[1]2026 január'!Z7 ) | AD9: =IF('[1]2026 január'!AA7=0, "", '[1]2026 január'!AA7 ) -> Vásárlás | AE9: =IF('[1]2026 január'!AB$7=0, "", '[1]2026 január'!AB$7 ) -> Vip töltés | AF9: =IF('[1]2026 január'!AC$7=0, "", '[1]2026 január'!AC$7 ) | AG9: =IF('[1]2026 január'!AD$7=0, "", '[1]2026 január'!AD$7 ) | AH9: =IF('[1]2026 január'!AE7=0, "", '[1]2026 január'!AE7 ) | AI9: =IF('[1]2026 január'!AF7=0, "", '[1]2026 január'!AF7 ) | AJ9: =IF('[1]2026 január'!AG7=0, "", '[1]2026 január'!AG7 ) | AK9: =IF('[1]2026 január'!AH7=0, "", '[1]2026 január'!AH7 )
A10: 46029 | B10: 423525 | C10: 850 | D10: 247930 | F10: 161945 | G10: 20510 | H10: 390215 | I10: 390215 | J10: 1012 | K10: 213546661 | P10: =IF('[1]2026 január'!B$8=0, "", '[1]2026 január'!B$8 ) -> 410725 | Q10: =IF(OR('[1]2026 január'!G8=0, ISBLANK('[1]2026 január'!G8)), "", '[1]2026 január'!G8 ) | R10: ='[1]2026 január'!W8 -> 7190 | V10: =IF('[1]2026 január'!S8=0, "", '[1]2026 január'!S8 ) -> 171457 | W10: =IF('[1]2026 január'!T8=0, "", '[1]2026 január'!T8 ) -> 20510 | X10: =IF('[1]2026 január'!U8=0, "", '[1]2026 január'!U8 ) | Y10: =IF('[1]2026 január'!V8=0, "", '[1]2026 január'!V8 ) | Z10: =IF('[1]2026 január'!W8=0, "", '[1]2026 január'!W8 ) -> 7190 | AA10: =IF('[1]2026 január'!X8=0, "", '[1]2026 január'!X8 ) | AB10: =IF('[1]2026 január'!Y8=0, "", '[1]2026 január'!Y8 ) -> 184777 | AC10: =IF('[1]2026 január'!Z8=0, "", '[1]2026 január'!Z8 ) | AD10: =IF('[1]2026 január'!AA8=0, "", '[1]2026 január'!AA8 ) -> Matrica | AE10: =IF('[1]2026 január'!AB$8=0, "", '[1]2026 január'!AB$8 ) | AF10: =IF('[1]2026 január'!AC$8=0, "", '[1]2026 január'!AC$8 ) | AG10: =IF('[1]2026 január'!AD$8=0, "", '[1]2026 január'!AD$8 ) | AH10: =IF('[1]2026 január'!AE8=0, "", '[1]2026 január'!AE8 ) | AI10: =IF('[1]2026 január'!AF8=0, "", '[1]2026 január'!AF8 ) | AJ10: =IF('[1]2026 január'!AG8=0, "", '[1]2026 január'!AG8 ) | AK10: =IF('[1]2026 január'!AH8=0, "", '[1]2026 január'!AH8 )
A11: 46030 | B11: 459800 | C11: 1150 | D11: 275605 | F11: 196505 | G11: 28825 | H11: 444435 | I11: 444435 | J11: 1013 | K11: 214019921 | P11: =IF('[1]2026 január'!B$9=0, "", '[1]2026 január'!B$9 ) -> 443260 | Q11: =IF(OR('[1]2026 január'!G9=0, ISBLANK('[1]2026 január'!G9)), "", '[1]2026 január'!G9 ) | R11: ='[1]2026 január'!W9 -> 0 | V11: =IF('[1]2026 január'!S9=0, "", '[1]2026 január'!S9 ) -> 184777 | W11: =IF('[1]2026 január'!T9=0, "", '[1]2026 január'!T9 ) -> -1175 | X11: =IF('[1]2026 január'!U9=0, "", '[1]2026 január'!U9 ) | Y11: =IF('[1]2026 január'!V9=0, "", '[1]2026 január'!V9 ) -> 22997 | Z11: =IF('[1]2026 január'!W9=0, "", '[1]2026 január'!W9 ) | AA11: =IF('[1]2026 január'!X9=0, "", '[1]2026 január'!X9 ) | AB11: =IF('[1]2026 január'!Y9=0, "", '[1]2026 január'!Y9 ) -> 160605 | AC11: =IF('[1]2026 január'!Z9=0, "", '[1]2026 január'!Z9 ) | AD11: =IF('[1]2026 január'!AA9=0, "", '[1]2026 január'!AA9 ) -> Media Markt | AE11: =IF('[1]2026 január'!AB$9=0, "", '[1]2026 január'!AB$9 ) | AF11: =IF('[1]2026 január'!AC$9=0, "", '[1]2026 január'!AC$9 ) | AG11: =IF('[1]2026 január'!AD$9=0, "", '[1]2026 január'!AD$9 ) | AH11: =IF('[1]2026 január'!AE9=0, "", '[1]2026 január'!AE9 ) | AI11: =IF('[1]2026 január'!AF9=0, "", '[1]2026 január'!AF9 ) | AJ11: =IF('[1]2026 január'!AG9=0, "", '[1]2026 január'!AG9 ) | AK11: =IF('[1]2026 január'!AH9=0, "", '[1]2026 január'!AH9 )
A12: 46031 | B12: 377780 | C12: 700 | D12: 301850 | F12: 108675 | G12: 12365 | H12: 398860 | I12: 398860 | J12: 1014 | K12: 214431146 | P12: =IF('[1]2026 január'!B$10=0, "", '[1]2026 január'!B$10 ) -> 361225 | Q12: =IF(OR('[1]2026 január'!G10=0, ISBLANK('[1]2026 január'!G10)), "", '[1]2026 január'!G10 ) | R12: ='[1]2026 január'!W10 -> 0 | V12: =IF('[1]2026 január'!S10=0, "", '[1]2026 január'!S10 ) -> 160605 | W12: =IF('[1]2026 január'!T10=0, "", '[1]2026 január'!T10 ) -> -37735 | X12: =IF('[1]2026 január'!U10=0, "", '[1]2026 január'!U10 ) -> 104000 | Y12: =IF('[1]2026 január'!V10=0, "", '[1]2026 január'!V10 ) -> 79850 | Z12: =IF('[1]2026 január'!W10=0, "", '[1]2026 január'!W10 ) | AA12: =IF('[1]2026 január'!X10=0, "", '[1]2026 január'!X10 ) | AB12: =IF('[1]2026 január'!Y10=0, "", '[1]2026 január'!Y10 ) -> 147020 | AC12: =IF('[1]2026 január'!Z10=0, "", '[1]2026 január'!Z10 ) | AD12: =IF('[1]2026 január'!AA10=0, "", '[1]2026 január'!AA10 ) -> Vásárlás, Vip töltés, Melinda, Parkolás | AE12: =IF('[1]2026 január'!AB$10=0, "", '[1]2026 január'!AB$10 ) | AF12: =IF('[1]2026 január'!AC$10=0, "", '[1]2026 január'!AC$10 ) | AG12: =IF('[1]2026 január'!AD$10=0, "", '[1]2026 január'!AD$10 ) | AH12: =IF('[1]2026 január'!AE10=0, "", '[1]2026 január'!AE10 ) | AI12: =IF('[1]2026 január'!AF10=0, "", '[1]2026 január'!AF10 ) | AJ12: =IF('[1]2026 január'!AG10=0, "", '[1]2026 január'!AG10 ) | AK12: =IF('[1]2026 január'!AH10=0, "", '[1]2026 január'!AH10 )
A13: 46032 | P13: =IF('[1]2026 január'!B$11=0, "", '[1]2026 január'!B$11 ) | Q13: =IF(OR('[1]2026 január'!G11=0, ISBLANK('[1]2026 január'!G11)), "", '[1]2026 január'!G11 ) | R13: ='[1]2026 január'!W11 -> 0 | V13: =IF('[1]2026 január'!S11=0, "", '[1]2026 január'!S11 ) -> 147020 | W13: =IF('[1]2026 január'!T11=0, "", '[1]2026 január'!T11 ) | X13: =IF('[1]2026 január'!U11=0, "", '[1]2026 január'!U11 ) | Y13: =IF('[1]2026 január'!V11=0, "", '[1]2026 január'!V11 ) | Z13: =IF('[1]2026 január'!W11=0, "", '[1]2026 január'!W11 ) | AA13: =IF('[1]2026 január'!X11=0, "", '[1]2026 január'!X11 ) | AB13: =IF('[1]2026 január'!Y11=0, "", '[1]2026 január'!Y11 ) -> 147020 | AC13: =IF('[1]2026 január'!Z11=0, "", '[1]2026 január'!Z11 ) | AD13: =IF('[1]2026 január'!AA11=0, "", '[1]2026 január'!AA11 ) | AE13: =IF('[1]2026 január'!AB$11=0, "", '[1]2026 január'!AB$11 ) | AF13: =IF('[1]2026 január'!AC$11=0, "", '[1]2026 január'!AC$11 ) | AG13: =IF('[1]2026 január'!AD$11=0, "", '[1]2026 január'!AD$11 ) | AH13: =IF('[1]2026 január'!AE11=0, "", '[1]2026 január'!AE11 ) | AI13: =IF('[1]2026 január'!AF11=0, "", '[1]2026 január'!AF11 ) | AJ13: =IF('[1]2026 január'!AG11=0, "", '[1]2026 január'!AG11 ) | AK13: =IF('[1]2026 január'!AH11=0, "", '[1]2026 január'!AH11 )
A14: 46033 | P14: =IF('[1]2026 január'!B$12=0, "", '[1]2026 január'!B$12 ) | Q14: =IF(OR('[1]2026 január'!G12=0, ISBLANK('[1]2026 január'!G12)), "", '[1]2026 január'!G12 ) | R14: ='[1]2026 január'!W12 -> 0 | V14: =IF('[1]2026 január'!S12=0, "", '[1]2026 január'!S12 ) -> 147020 | W14: =IF('[1]2026 január'!T12=0, "", '[1]2026 január'!T12 ) | X14: =IF('[1]2026 január'!U12=0, "", '[1]2026 január'!U12 ) | Y14: =IF('[1]2026 január'!V12=0, "", '[1]2026 január'!V12 ) | Z14: =IF('[1]2026 január'!W12=0, "", '[1]2026 január'!W12 ) | AA14: =IF('[1]2026 január'!X12=0, "", '[1]2026 január'!X12 ) | AB14: =IF('[1]2026 január'!Y12=0, "", '[1]2026 január'!Y12 ) -> 147020 | AC14: =IF('[1]2026 január'!Z12=0, "", '[1]2026 január'!Z12 ) | AD14: =IF('[1]2026 január'!AA12=0, "", '[1]2026 január'!AA12 ) | AE14: =IF('[1]2026 január'!AB$12=0, "", '[1]2026 január'!AB$12 ) | AF14: =IF('[1]2026 január'!AC$12=0, "", '[1]2026 január'!AC$12 ) | AG14: =IF('[1]2026 január'!AD$12=0, "", '[1]2026 január'!AD$12 ) | AH14: =IF('[1]2026 január'!AE12=0, "", '[1]2026 január'!AE12 ) | AI14: =IF('[1]2026 január'!AF12=0, "", '[1]2026 január'!AF12 ) | AJ14: =IF('[1]2026 január'!AG12=0, "", '[1]2026 január'!AG12 ) | AK14: =IF('[1]2026 január'!AH12=0, "", '[1]2026 január'!AH12 )
A15: 46034 | B15: 359915 | C15: 1000 | D15: 203450 | F15: 148695 | G15: 18725 | H15: 332630 | I15: 332630 | J15: 1015 | K15: 214784291 | M15: 1790 | N15: van | P15: =IF('[1]2026 január'!B$13=0, "", '[1]2026 január'!B$13 ) -> 351355 | Q15: =IF(OR('[1]2026 január'!G13=0, ISBLANK('[1]2026 január'!G13)), "", '[1]2026 január'!G13 ) | R15: ='[1]2026 január'!W13 -> 0 | V15: =IF('[1]2026 január'!S13=0, "", '[1]2026 január'!S13 ) -> 147020 | W15: =IF('[1]2026 január'!T13=0, "", '[1]2026 január'!T13 ) -> 18725 | X15: =IF('[1]2026 január'!U13=0, "", '[1]2026 január'!U13 ) | Y15: =IF('[1]2026 január'!V13=0, "", '[1]2026 január'!V13 ) | Z15: =IF('[1]2026 január'!W13=0, "", '[1]2026 január'!W13 ) | AA15: =IF('[1]2026 január'!X13=0, "", '[1]2026 január'!X13 ) | AB15: =IF('[1]2026 január'!Y13=0, "", '[1]2026 január'!Y13 ) -> 165745 | AC15: =IF('[1]2026 január'!Z13=0, "", '[1]2026 január'!Z13 ) | AD15: =IF('[1]2026 január'!AA13=0, "", '[1]2026 január'!AA13 ) | AE15: =IF('[1]2026 január'!AB$13=0, "", '[1]2026 január'!AB$13 ) | AF15: =IF('[1]2026 január'!AC$13=0, "", '[1]2026 január'!AC$13 ) | AG15: =IF('[1]2026 január'!AD$13=0, "", '[1]2026 január'!AD$13 ) | AH15: =IF('[1]2026 január'!AE13=0, "", '[1]2026 január'!AE13 ) | AI15: =IF('[1]2026 január'!AF13=0, "", '[1]2026 január'!AF13 ) | AJ15: =IF('[1]2026 január'!AG13=0, "", '[1]2026 január'!AG13 ) | AK15: =IF('[1]2026 január'!AH13=0, "", '[1]2026 január'!AH13 )
A16: 46035 | B16: 479540 | C16: 950 | D16: 312260 | F16: 153045 | G16: 23625 | H16: 442630 | I16: 442630 | J16: 1016 | K16: 215250546 | P16: =IF('[1]2026 január'!B$14=0, "", '[1]2026 január'!B$14 ) -> 466255 | Q16: =IF(OR('[1]2026 január'!G14=0, ISBLANK('[1]2026 január'!G14)), "", '[1]2026 január'!G14 ) | R16: ='[1]2026 január'!W14 -> 0 | V16: =IF('[1]2026 január'!S14=0, "", '[1]2026 január'!S14 ) -> 165745 | W16: =IF('[1]2026 január'!T14=0, "", '[1]2026 január'!T14 ) -> 23625 | X16: =IF('[1]2026 január'!U14=0, "", '[1]2026 január'!U14 ) | Y16: =IF('[1]2026 január'!V14=0, "", '[1]2026 január'!V14 ) | Z16: =IF('[1]2026 január'!W14=0, "", '[1]2026 január'!W14 ) | AA16: =IF('[1]2026 január'!X14=0, "", '[1]2026 január'!X14 ) | AB16: =IF('[1]2026 január'!Y14=0, "", '[1]2026 január'!Y14 ) -> 189370 | AC16: =IF('[1]2026 január'!Z14=0, "", '[1]2026 január'!Z14 ) | AD16: =IF('[1]2026 január'!AA14=0, "", '[1]2026 január'!AA14 ) | AE16: =IF('[1]2026 január'!AB$14=0, "", '[1]2026 január'!AB$14 ) | AF16: =IF('[1]2026 január'!AC$14=0, "", '[1]2026 január'!AC$14 ) | AG16: =IF('[1]2026 január'!AD$14=0, "", '[1]2026 január'!AD$14 ) | AH16: =IF('[1]2026 január'!AE14=0, "", '[1]2026 január'!AE14 ) | AI16: =IF('[1]2026 január'!AF14=0, "", '[1]2026 január'!AF14 ) | AJ16: =IF('[1]2026 január'!AG14=0, "", '[1]2026 január'!AG14 ) | AK16: =IF('[1]2026 január'!AH14=0, "", '[1]2026 január'!AH14 )
A17: 46036 | B17: 363510 | C17: 700 | D17: 240091 | F17: 110000 | G17: 20045 | H17: 330745 | I17: 371745 | J17: 1017 | K17: 215601337 | N17: ÁFA-s számla | P17: =IF('[1]2026 január'!B$15=0, "", '[1]2026 január'!B$15 ) -> 350790 | Q17: =IF(OR('[1]2026 január'!G15=0, ISBLANK('[1]2026 január'!G15)), "", '[1]2026 január'!G15 ) | R17: ='[1]2026 január'!W15 -> 0 | V17: =IF('[1]2026 január'!S15=0, "", '[1]2026 január'!S15 ) -> 189370 | W17: =IF('[1]2026 január'!T15=0, "", '[1]2026 január'!T15 ) -> -20955 | X17: =IF('[1]2026 január'!U15=0, "", '[1]2026 január'!U15 ) -> 41000 | Y17: =IF('[1]2026 január'!V15=0, "", '[1]2026 január'!V15 ) -> 63000 | Z17: =IF('[1]2026 január'!W15=0, "", '[1]2026 január'!W15 ) | AA17: =IF('[1]2026 január'!X15=0, "", '[1]2026 január'!X15 ) | AB17: =IF('[1]2026 január'!Y15=0, "", '[1]2026 január'!Y15 ) -> 146415 | AC17: =IF('[1]2026 január'!Z15=0, "", '[1]2026 január'!Z15 ) | AD17: =IF('[1]2026 január'!AA15=0, "", '[1]2026 január'!AA15 ) -> Márk, Vip töltés | AE17: =IF('[1]2026 január'!AB$15=0, "", '[1]2026 január'!AB$15 ) | AF17: =IF('[1]2026 január'!AC$15=0, "", '[1]2026 január'!AC$15 ) | AG17: =IF('[1]2026 január'!AD$15=0, "", '[1]2026 január'!AD$15 ) | AH17: =IF('[1]2026 január'!AE15=0, "", '[1]2026 január'!AE15 ) | AI17: =IF('[1]2026 január'!AF15=0, "", '[1]2026 január'!AF15 ) | AJ17: =IF('[1]2026 január'!AG15=0, "", '[1]2026 január'!AG15 ) | AK17: =IF('[1]2026 január'!AH15=0, "", '[1]2026 január'!AH15 )
A18: 46037 | B18: 335270 | C18: 800 | D18: 245235 | F18: 107715 | G18: 27940 | H18: 325810 | I18: 325810 | J18: 1018 | K18: 215955087 | P18: =IF('[1]2026 január'!B$16=0, "", '[1]2026 január'!B$16 ) -> 323750 | Q18: =IF(OR('[1]2026 január'!G16=0, ISBLANK('[1]2026 január'!G16)), "", '[1]2026 január'!G16 ) | R18: ='[1]2026 január'!W16 -> 0 | V18: =IF('[1]2026 január'!S16=0, "", '[1]2026 január'!S16 ) -> 146415 | W18: =IF('[1]2026 január'!T16=0, "", '[1]2026 január'!T16 ) -> -2060 | X18: =IF('[1]2026 január'!U16=0, "", '[1]2026 január'!U16 ) -> 30000 | Y18: =IF('[1]2026 január'!V16=0, "", '[1]2026 január'!V16 ) | Z18: =IF('[1]2026 január'!W16=0, "", '[1]2026 január'!W16 ) | AA18: =IF('[1]2026 január'!X16=0, "", '[1]2026 január'!X16 ) | AB18: =IF('[1]2026 január'!Y16=0, "", '[1]2026 január'!Y16 ) -> 174355 | AC18: =IF('[1]2026 január'!Z16=0, "", '[1]2026 január'!Z16 ) | AD18: =IF('[1]2026 január'!AA16=0, "", '[1]2026 január'!AA16 ) -> Vip töltés | AE18: =IF('[1]2026 január'!AB$16=0, "", '[1]2026 január'!AB$16 ) | AF18: =IF('[1]2026 január'!AC$16=0, "", '[1]2026 január'!AC$16 ) | AG18: =IF('[1]2026 január'!AD$16=0, "", '[1]2026 január'!AD$16 ) | AH18: =IF('[1]2026 január'!AE16=0, "", '[1]2026 január'!AE16 ) | AI18: =IF('[1]2026 január'!AF16=0, "", '[1]2026 január'!AF16 ) | AJ18: =IF('[1]2026 január'!AG16=0, "", '[1]2026 január'!AG16 ) | AK18: =IF('[1]2026 január'!AH16=0, "", '[1]2026 január'!AH16 )
A19: 46038 | B19: 284595 | C19: 550 | D19: 160155 | F19: 120070 | G19: 24505 | H19: 256270 | I19: 256270 | J19: 1019 | K19: 216235862 | P19: =IF('[1]2026 január'!B$17=0, "", '[1]2026 január'!B$17 ) -> 280775 | Q19: =IF(OR('[1]2026 január'!G17=0, ISBLANK('[1]2026 január'!G17)), "", '[1]2026 január'!G17 ) | R19: ='[1]2026 január'!W17 -> 0 | V19: =IF('[1]2026 január'!S17=0, "", '[1]2026 január'!S17 ) -> 174355 | W19: =IF('[1]2026 január'!T17=0, "", '[1]2026 január'!T17 ) -> 24505 | X19: =IF('[1]2026 január'!U17=0, "", '[1]2026 január'!U17 ) | Y19: =IF('[1]2026 január'!V17=0, "", '[1]2026 január'!V17 ) -> 99015 | Z19: =IF('[1]2026 január'!W17=0, "", '[1]2026 január'!W17 ) | AA19: =IF('[1]2026 január'!X17=0, "", '[1]2026 január'!X17 ) | AB19: =IF('[1]2026 január'!Y17=0, "", '[1]2026 január'!Y17 ) -> 99845 | AC19: =IF('[1]2026 január'!Z17=0, "", '[1]2026 január'!Z17 ) | AD19: =IF('[1]2026 január'!AA17=0, "", '[1]2026 január'!AA17 ) -> Melinda | AE19: =IF('[1]2026 január'!AB$17=0, "", '[1]2026 január'!AB$17 ) | AF19: =IF('[1]2026 január'!AC$17=0, "", '[1]2026 január'!AC$17 ) | AG19: =IF('[1]2026 január'!AD$17=0, "", '[1]2026 január'!AD$17 ) | AH19: =IF('[1]2026 január'!AE17=0, "", '[1]2026 január'!AE17 ) | AI19: =IF('[1]2026 január'!AF17=0, "", '[1]2026 január'!AF17 ) | AJ19: =IF('[1]2026 január'!AG17=0, "", '[1]2026 január'!AG17 ) | AK19: =IF('[1]2026 január'!AH17=0, "", '[1]2026 január'!AH17 )
A20: 46039 | P20: =IF('[1]2026 január'!B$18=0, "", '[1]2026 január'!B$18 ) | Q20: =IF(OR('[1]2026 január'!G18=0, ISBLANK('[1]2026 január'!G18)), "", '[1]2026 január'!G18 ) | R20: ='[1]2026 január'!W18 -> 0 | V20: =IF('[1]2026 január'!S18=0, "", '[1]2026 január'!S18 ) -> 99845 | W20: =IF('[1]2026 január'!T18=0, "", '[1]2026 január'!T18 ) | X20: =IF('[1]2026 január'!U18=0, "", '[1]2026 január'!U18 ) | Y20: =IF('[1]2026 január'!V18=0, "", '[1]2026 január'!V18 ) | Z20: =IF('[1]2026 január'!W18=0, "", '[1]2026 január'!W18 ) | AA20: =IF('[1]2026 január'!X18=0, "", '[1]2026 január'!X18 ) | AB20: =IF('[1]2026 január'!Y18=0, "", '[1]2026 január'!Y18 ) -> 99845 | AC20: =IF('[1]2026 január'!Z18=0, "", '[1]2026 január'!Z18 ) | AD20: =IF('[1]2026 január'!AA18=0, "", '[1]2026 január'!AA18 ) | AE20: =IF('[1]2026 január'!AB$18=0, "", '[1]2026 január'!AB$18 ) | AF20: =IF('[1]2026 január'!AC$18=0, "", '[1]2026 január'!AC$18 ) | AG20: =IF('[1]2026 január'!AD$18=0, "", '[1]2026 január'!AD$18 ) | AH20: =IF('[1]2026 január'!AE18=0, "", '[1]2026 január'!AE18 ) | AI20: =IF('[1]2026 január'!AF18=0, "", '[1]2026 január'!AF18 ) | AJ20: =IF('[1]2026 január'!AG18=0, "", '[1]2026 január'!AG18 ) | AK20: =IF('[1]2026 január'!AH18=0, "", '[1]2026 január'!AH18 )
A21: 46040 | P21: =IF('[1]2026 január'!B$19=0, "", '[1]2026 január'!B$19 ) | Q21: =IF(OR('[1]2026 január'!G19=0, ISBLANK('[1]2026 január'!G19)), "", '[1]2026 január'!G19 ) | R21: ='[1]2026 január'!W19 -> 0 | V21: =IF('[1]2026 január'!S19=0, "", '[1]2026 január'!S19 ) -> 99845 | W21: =IF('[1]2026 január'!T19=0, "", '[1]2026 január'!T19 ) | X21: =IF('[1]2026 január'!U19=0, "", '[1]2026 január'!U19 ) | Y21: =IF('[1]2026 január'!V19=0, "", '[1]2026 január'!V19 ) | Z21: =IF('[1]2026 január'!W19=0, "", '[1]2026 január'!W19 ) | AA21: =IF('[1]2026 január'!X19=0, "", '[1]2026 január'!X19 ) | AB21: =IF('[1]2026 január'!Y19=0, "", '[1]2026 január'!Y19 ) -> 99845 | AC21: =IF('[1]2026 január'!Z19=0, "", '[1]2026 január'!Z19 ) | AD21: =IF('[1]2026 január'!AA19=0, "", '[1]2026 január'!AA19 ) | AE21: =IF('[1]2026 január'!AB$19=0, "", '[1]2026 január'!AB$19 ) | AF21: =IF('[1]2026 január'!AC$19=0, "", '[1]2026 január'!AC$19 ) | AG21: =IF('[1]2026 január'!AD$19=0, "", '[1]2026 január'!AD$19 ) | AH21: =IF('[1]2026 január'!AE19=0, "", '[1]2026 január'!AE19 ) | AI21: =IF('[1]2026 január'!AF19=0, "", '[1]2026 január'!AF19 ) | AJ21: =IF('[1]2026 január'!AG19=0, "", '[1]2026 január'!AG19 ) | AK21: =IF('[1]2026 január'!AH19=0, "", '[1]2026 január'!AH19 )
A22: 46041 | B22: 311770 | C22: 650 | D22: 139715 | F22: 154705 | G22: 24775 | H22: 270295 | I22: 270295 | J22: 1020 | K22: 216530932 | P22: =IF('[1]2026 január'!B$20=0, "", '[1]2026 január'!B$20 ) -> 295070 | Q22: =IF(OR('[1]2026 január'!G20=0, ISBLANK('[1]2026 január'!G20)), "", '[1]2026 január'!G20 ) | R22: ='[1]2026 január'!W20 -> 0 | V22: =IF('[1]2026 január'!S20=0, "", '[1]2026 január'!S20 ) -> 99845 | W22: =IF('[1]2026 január'!T20=0, "", '[1]2026 január'!T20 ) -> 24775 | X22: =IF('[1]2026 január'!U20=0, "", '[1]2026 január'!U20 ) | Y22: =IF('[1]2026 január'!V20=0, "", '[1]2026 január'!V20 ) | Z22: =IF('[1]2026 január'!W20=0, "", '[1]2026 január'!W20 ) | AA22: =IF('[1]2026 január'!X20=0, "", '[1]2026 január'!X20 ) | AB22: =IF('[1]2026 január'!Y20=0, "", '[1]2026 január'!Y20 ) -> 124620 | AC22: =IF('[1]2026 január'!Z20=0, "", '[1]2026 január'!Z20 ) | AD22: =IF('[1]2026 január'!AA20=0, "", '[1]2026 január'!AA20 ) | AE22: =IF('[1]2026 január'!AB$20=0, "", '[1]2026 január'!AB$20 ) | AF22: =IF('[1]2026 január'!AC$20=0, "", '[1]2026 január'!AC$20 ) | AG22: =IF('[1]2026 január'!AD$20=0, "", '[1]2026 január'!AD$20 ) | AH22: =IF('[1]2026 január'!AE20=0, "", '[1]2026 január'!AE20 ) | AI22: =IF('[1]2026 január'!AF20=0, "", '[1]2026 január'!AF20 ) | AJ22: =IF('[1]2026 január'!AG20=0, "", '[1]2026 január'!AG20 ) | AK22: =IF('[1]2026 január'!AH20=0, "", '[1]2026 január'!AH20 )
A23: 46042 | B23: 401625 | C23: 700 | D23: 244105 | F23: 140370 | G23: 28320 | H23: 356855 | I23: 356855 | J23: 1021 | K23: 216916107 | P23: =IF('[1]2026 január'!B$21=0, "", '[1]2026 január'!B$21 ) -> 385175 | Q23: =IF(OR('[1]2026 január'!G21=0, ISBLANK('[1]2026 január'!G21)), "", '[1]2026 január'!G21 ) | R23: ='[1]2026 január'!W21 -> 0 | V23: =IF('[1]2026 január'!S21=0, "", '[1]2026 január'!S21 ) -> 124620 | W23: =IF('[1]2026 január'!T21=0, "", '[1]2026 január'!T21 ) -> 28320 | X23: =IF('[1]2026 január'!U21=0, "", '[1]2026 január'!U21 ) | Y23: =IF('[1]2026 január'!V21=0, "", '[1]2026 január'!V21 ) | Z23: =IF('[1]2026 január'!W21=0, "", '[1]2026 január'!W21 ) | AA23: =IF('[1]2026 január'!X21=0, "", '[1]2026 január'!X21 ) | AB23: =IF('[1]2026 január'!Y21=0, "", '[1]2026 január'!Y21 ) -> 152940 | AC23: =IF('[1]2026 január'!Z21=0, "", '[1]2026 január'!Z21 ) | AD23: =IF('[1]2026 január'!AA21=0, "", '[1]2026 január'!AA21 ) | AE23: =IF('[1]2026 január'!AB$21=0, "", '[1]2026 január'!AB$21 ) | AF23: =IF('[1]2026 január'!AC$21=0, "", '[1]2026 január'!AC$21 ) | AG23: =IF('[1]2026 január'!AD$21=0, "", '[1]2026 január'!AD$21 ) | AH23: =IF('[1]2026 január'!AE21=0, "", '[1]2026 január'!AE21 ) | AI23: =IF('[1]2026 január'!AF21=0, "", '[1]2026 január'!AF21 ) | AJ23: =IF('[1]2026 január'!AG21=0, "", '[1]2026 január'!AG21 ) | AK23: =IF('[1]2026 január'!AH21=0, "", '[1]2026 január'!AH21 )
A24: 46043 | B24: 305995 | C24: 1250 | D24: 158570 | F24: 133445 | G24: 25800 | H24: 267465 | I24: 267465 | J24: 1022 | K24: 217209372 | P24: =IF('[1]2026 január'!B$22=0, "", '[1]2026 január'!B$22 ) -> 293265 | Q24: =IF(OR('[1]2026 január'!G22=0, ISBLANK('[1]2026 január'!G22)), "", '[1]2026 január'!G22 ) | R24: ='[1]2026 január'!W22 -> 0 | V24: =IF('[1]2026 január'!S22=0, "", '[1]2026 január'!S22 ) -> 152940 | W24: =IF('[1]2026 január'!T22=0, "", '[1]2026 január'!T22 ) -> 25800 | X24: =IF('[1]2026 január'!U22=0, "", '[1]2026 január'!U22 ) | Y24: =IF('[1]2026 január'!V22=0, "", '[1]2026 január'!V22 ) | Z24: =IF('[1]2026 január'!W22=0, "", '[1]2026 január'!W22 ) | AA24: =IF('[1]2026 január'!X22=0, "", '[1]2026 január'!X22 ) | AB24: =IF('[1]2026 január'!Y22=0, "", '[1]2026 január'!Y22 ) -> 178740 | AC24: =IF('[1]2026 január'!Z22=0, "", '[1]2026 január'!Z22 ) | AD24: =IF('[1]2026 január'!AA22=0, "", '[1]2026 január'!AA22 ) | AE24: =IF('[1]2026 január'!AB$22=0, "", '[1]2026 január'!AB$22 ) | AF24: =IF('[1]2026 január'!AC$22=0, "", '[1]2026 január'!AC$22 ) | AG24: =IF('[1]2026 január'!AD$22=0, "", '[1]2026 január'!AD$22 ) | AH24: =IF('[1]2026 január'!AE22=0, "", '[1]2026 január'!AE22 ) | AI24: =IF('[1]2026 január'!AF22=0, "", '[1]2026 január'!AF22 ) | AJ24: =IF('[1]2026 január'!AG22=0, "", '[1]2026 január'!AG22 ) | AK24: =IF('[1]2026 január'!AH22=0, "", '[1]2026 január'!AH22 )
A25: 46044 | B25: 387015 | C25: 900 | D25: 201465 | F25: 158810 | G25: 26950 | H25: 334255 | I25: 334255 | J25: 1023 | K25: 217570547 | P25: =IF('[1]2026 január'!B$23=0, "", '[1]2026 január'!B$23 ) -> 361175 | Q25: =IF(OR('[1]2026 január'!G23=0, ISBLANK('[1]2026 január'!G23)), "", '[1]2026 január'!G23 ) | R25: ='[1]2026 január'!W23 -> 0 | V25: =IF('[1]2026 január'!S23=0, "", '[1]2026 január'!S23 ) -> 178740 | W25: =IF('[1]2026 január'!T23=0, "", '[1]2026 január'!T23 ) -> 26950 | X25: =IF('[1]2026 január'!U23=0, "", '[1]2026 január'!U23 ) | Y25: =IF('[1]2026 január'!V23=0, "", '[1]2026 január'!V23 ) | Z25: =IF('[1]2026 január'!W23=0, "", '[1]2026 január'!W23 ) | AA25: =IF('[1]2026 január'!X23=0, "", '[1]2026 január'!X23 ) | AB25: =IF('[1]2026 január'!Y23=0, "", '[1]2026 január'!Y23 ) -> 205690 | AC25: =IF('[1]2026 január'!Z23=0, "", '[1]2026 január'!Z23 ) | AD25: =IF('[1]2026 január'!AA23=0, "", '[1]2026 január'!AA23 ) | AE25: =IF('[1]2026 január'!AB$23=0, "", '[1]2026 január'!AB$23 ) | AF25: =IF('[1]2026 január'!AC$23=0, "", '[1]2026 január'!AC$23 ) | AG25: =IF('[1]2026 január'!AD$23=0, "", '[1]2026 január'!AD$23 ) | AH25: =IF('[1]2026 január'!AE23=0, "", '[1]2026 január'!AE23 ) | AI25: =IF('[1]2026 január'!AF23=0, "", '[1]2026 január'!AF23 ) | AJ25: =IF('[1]2026 január'!AG23=0, "", '[1]2026 január'!AG23 ) | AK25: =IF('[1]2026 január'!AH23=0, "", '[1]2026 január'!AH23 )
A26: 46045 | B26: 309170 | C26: 750 | D26: 194725 | F26: 97045 | G26: 8790 | H26: 283730 | I26: 283730 | J26: 1024 | K26: 217863067 | P26: =IF('[1]2026 január'!B$24=0, "", '[1]2026 január'!B$24 ) -> 292520 | Q26: =IF(OR('[1]2026 január'!G24=0, ISBLANK('[1]2026 január'!G24)), "", '[1]2026 január'!G24 ) | R26: ='[1]2026 január'!W24 -> 0 | V26: =IF('[1]2026 január'!S24=0, "", '[1]2026 január'!S24 ) -> 205690 | W26: =IF('[1]2026 január'!T24=0, "", '[1]2026 január'!T24 ) -> 8790 | X26: =IF('[1]2026 január'!U24=0, "", '[1]2026 január'!U24 ) | Y26: =IF('[1]2026 január'!V24=0, "", '[1]2026 január'!V24 ) -> 64015 | Z26: =IF('[1]2026 január'!W24=0, "", '[1]2026 január'!W24 ) | AA26: =IF('[1]2026 január'!X24=0, "", '[1]2026 január'!X24 ) | AB26: =IF('[1]2026 január'!Y24=0, "", '[1]2026 január'!Y24 ) -> 150465 | AC26: =IF('[1]2026 január'!Z24=0, "", '[1]2026 január'!Z24 ) | AD26: =IF('[1]2026 január'!AA24=0, "", '[1]2026 január'!AA24 ) -> Melinda | AE26: =IF('[1]2026 január'!AB$24=0, "", '[1]2026 január'!AB$24 ) | AF26: =IF('[1]2026 január'!AC$24=0, "", '[1]2026 január'!AC$24 ) | AG26: =IF('[1]2026 január'!AD$24=0, "", '[1]2026 január'!AD$24 ) | AH26: =IF('[1]2026 január'!AE24=0, "", '[1]2026 január'!AE24 ) | AI26: =IF('[1]2026 január'!AF24=0, "", '[1]2026 január'!AF24 ) | AJ26: =IF('[1]2026 január'!AG24=0, "", '[1]2026 január'!AG24 ) | AK26: =IF('[1]2026 január'!AH24=0, "", '[1]2026 január'!AH24 )
