Workbook

Sheet 2026 éves
D2: SIM kártya | E2: Éves Felülvizsgálat | F2: Szolgáltató | G2: Január | I2: Február | K2: Március | M2: Április | O2: Május | Q2: Június | S2: Július | U2: Augusztus | W2: Szeptember | Y2: Október | AA2: November | AC2: December
G3: összesen | H3: kp | I3: összesen | J3: kp | K3: összesen | L3: kp | M3: összesen | N3: kp | O3: összesen | P3: kp | Q3: összesen | R3: kp | S3: összesen | T3: kp | U3: összesen | V3: kp | W3: összesen | X3: kp | Y3: összesen | Z3: kp | AA3: összesen | AB3: kp | AC3: összesen | AD3: kp
B4: Államkincstár | C4: =MÁK!A1 -> AP A13610440 | G4: ='202601'!L3 -> 7171251.5 | H4: ='202601'!J3 -> 459515
B6: Knorr105 | C6: =Knorr105!A1 -> AP A09111376 | G6: ='202601'!L5 -> 8507266 | H6: ='202601'!J5 -> 7190
B7: Knorr105 | C7: =Knorr105!Q1 -> AP A24010154 | G7: ='202601'!L6 -> 0.5 | H7: ='202601'!J6 -> 0
B8: Knorr105 | C8: =Knorr105!AG1 -> AP A13609805 | D8: 861075025184672 | F8: Mobil Adat | G8: ='202601'!L7 -> 7283289.5 | H8: ='202601'!J7 -> 0
B9: Knorr105 | C9: AP A09110892 | D9: 89430301901300660519 | F9: Telekom
B11: Knorr86 | C11: =Knorr86!A1 -> AP A13607465 | D11: 861075020676789 | F11: Mobil Adat | G11: ='202601'!L10 -> 4985745.5 | H11: ='202601'!J10 -> 29890
B13: Knorr69 | C13: =Knorr69!A1 -> AP A09111377 | G13: ='202601'!L12 -> #REF! | H13: ='202601'!J12 -> #REF!
B15: KTI | C15: =KTI!A1 -> AP A13607773 | D15: 861075020652764 | F15: Mobil Adat | G15: ='202601'!L14 -> #REF! | H15: ='202601'!J14 -> #REF!
B17: Szentkirályi | C17: =Szentkiralyi!A1 -> AP A13611447
B19: RSR | C19: AP A09111370 | G19: ='202601'!L18 -> 987739.5 | H19: ='202601'!J18 -> 318535
B20: RSR | C20: AP A13610439 | D20: 861075024542649 | F20: Mobil Adat | G20: ='202601'!L19 -> 370942.5 | H20: ='202601'!J19 -> 115925
B22: Egyéb | C22: AP A13609679 | D22: 864403042171471 | F22: Mobil Adat | G22: ='202601'!#REF! -> #REF! | H22: ='202601'!#REF! -> #REF!
B23: Egyéb | C23: AP A09109974 | D23: 861075024542649 | F23: Mobil Adat | G23: ='202601'!L21 -> 0.5 | H23: ='202601'!J21 -> 0
B24: Egyéb | C24: AP A13608072 | D24: 861075020660809 | F24: Mobil Adat | G24: ='202601'!L22 -> 0.5 | H24: ='202601'!J22 -> 0
B25: Egyéb | C25: AP A13607772 | D25: 861075020660411 | F25: Telekom | G25: ='202601'!#REF! -> #REF! | H25: ='202601'!#REF! -> #REF!
B26: Összesen: | G26: =SUM(G4:G25) -> #REF! | H26: =SUM(H4:H25) -> #REF! | I26: =SUM(I4:I25) -> 0 | J26: =SUM(J4:J25) -> 0 | K26: =SUM(K4:K25) -> 0 | L26: =SUM(L4:L25) -> 0 | M26: =SUM(M4:M25) -> 0 | N26: =SUM(N4:N25) -> 0 | ... AD26: =SUM(AD4:AD25) -> 0
B28: SELEJT PÉNZTÁRGÉPEK
B30: A24004860 | C30: - | D30: 89430301902006414060 | F30: Telekom | G30: 2024.12.19. selejtezve | I30: szüneteltetve: 2025,05,14
B31: A24004855 | C31: AEE csere nincs bele | D31: 89430301902006411884 | F31: Telekom | I31: szüneteltetve: 2025,05,14
B32: A19503259 | C32: hiányzik a fogaskerék | D32: 861311007446874 | F32: Mobil Adat | G32: selejtezve
B33: A24004856 | C33: nem kommunikál a Navval | D33: 89430301902006410613 | F33: Telekom | G33: 2024.12.19. selejtezve
B34: A13607768 | D34: 861075020653549 | F34: Mobil Adat | G34: 2025.11.hóban selejtezve

Sheet 202602
C2: AP kód | D2: Nyitó zárás | E2: Záró zárás | F2: 0 | G2: 0.05 | H2: 0.18 | I2: 0.27 | J2: kp | K2: bankkártya | L2: Időszak összes | M2: Göngy. forgalom | O2: kp | P2: bk
B3: Államkincstár | C3: =MÁK!A1 -> AP A13610440 | F3: =MÁK!C35 -> 17250 | G3: =MÁK!D35 -> 4328426 | H3: =MÁK!E35 -> 0.18 | I3: =MÁK!F35 -> 2825575.3 | J3: =MÁK!G35 -> 459515 | L3: =SUM(F3:I3) -> 7171251.5 | O3: =J3+#REF! -> #REF! | P3: =SUM(L3:L3)-O3 -> #REF!
B5: Knorr105 | C5: =Knorr105!A1 -> AP A09111376 | F5: =Knorr105!C$35 -> 19250 | G5: =Knorr105!D$35 -> 8487866 | H5: =Knorr105!E$35 -> 150 | I5: =Knorr105!F$35 -> 0 | J5: =Knorr105!G$35 -> 7190 | L5: =SUM(F5:I5) -> 8507266 | O5: =J5+J6+J7 -> 12405 | P5: =SUM(L5:L7)-O5 -> 14663802
B6: Knorr105 | C6: =Knorr105!Q1 -> AP A24010154 | F6: =Knorr105!S$35 -> 57675 | G6: =Knorr105!T$35 -> 0.05 | H6: =Knorr105!U$35 -> 0.18 | I6: =Knorr105!V$35 -> 0.27 | J6: =Knorr105!W$35 -> 0 | L6: =SUM(F6:I6) -> 0.5
B7: Knorr105 | C7: =Knorr105!AG1 -> AP A13609805 | F7: =Knorr105!AI$35 -> 33940 | G7: =Knorr105!AJ$35 -> 7249299 | H7: =Knorr105!AK$35 -> 0.18 | I7: =Knorr105!AL$35 -> 50.27 | J7: =Knorr105!AM$35 -> 0 | L7: =SUM(F7:I7) -> 7283289.5
B8: Knorr105 | C8: AP A09110892
B10: Knorr86 | C10: =Knorr86!A1 -> AP A13607465 | F10: =Knorr86!C34 -> 26950 | G10: =Knorr86!D34 -> 4767430 | H10: =Knorr86!E34 -> 0.18 | I10: =Knorr86!F34 -> 191365.27 | J10: =Knorr86!G34 -> 29890 | L10: =SUM(F10:I10) -> 4985745.5 | O10: =J10 -> 29890 | P10: =L10-O10 -> 4955855.5
B12: Knorr69 | C12: =Knorr69!A1 -> AP A09111377 | F12: =Knorr69!#REF! -> #REF! | G12: =Knorr69!#REF! -> #REF! | H12: =Knorr69!#REF! -> #REF! | I12: =Knorr69!#REF! -> #REF! | J12: =Knorr69!#REF! -> #REF! | L12: =SUM(F12:I12) -> #REF! | O12: =J12 -> #REF! | P12: =L12-O12 -> #REF!
B14: KTI | C14: =KTI!A1 -> AP A13607773 | F14: =KTI!#REF! -> #REF! | G14: =KTI!#REF! -> #REF! | H14: =KTI!#REF! -> #REF! | I14: =KTI!#REF! -> #REF! | J14: =KTI!#REF! -> #REF! | L14: =SUM(F14:I14) -> #REF! | O14: =J14 -> #REF! | P14: =L14-O14 -> #REF!
B16: Szentkirályi | C16: AP A13611447
B18: RSR | C18: AP A09111370 | F18: =RSR!C34 -> 4396 | G18: =RSR!D34 -> 17170.05 | H18: =RSR!E34 -> 58570.18 | I18: =RSR!F34 -> 907603.27 | J18: =RSR!G34 -> 318535 | L18: =SUM(F18:I18) -> 987739.5 | O18: =SUM(J18:J19) -> 434460 | P18: =SUM(L18:L19)-O18 -> 924222
B19: RSR | C19: AP A13610439 | F19: =RSR!S34 -> 550 | G19: =RSR!T34 -> 322492.05 | H19: =RSR!U34 -> 0.18 | I19: =RSR!V34 -> 47900.27 | J19: =RSR!W34 -> 115925 | L19: =SUM(F19:I19) -> 370942.5
B21: Egyéb (RSR) | C21: ='Egyéb pénztárgépek'!M1 -> AP A13609679 | F21: ='Egyéb pénztárgépek'!N34 -> 0 | G21: ='Egyéb pénztárgépek'!O34 -> 0.05 | H21: ='Egyéb pénztárgépek'!P34 -> 0.18 | I21: ='Egyéb pénztárgépek'!Q34 -> 0.27 | J21: ='Egyéb pénztárgépek'!R34 -> 0 | L21: =SUM(F21:I21) -> 0.5
B22: Egyéb (RSR) | C22: ='Egyéb pénztárgépek'!AB1 -> AP A09109974 | F22: ='Egyéb pénztárgépek'!AC34 -> 0 | G22: ='Egyéb pénztárgépek'!AD34 -> 0.05 | H22: ='Egyéb pénztárgépek'!AE34 -> 0.18 | I22: ='Egyéb pénztárgépek'!AF34 -> 0.27 | J22: ='Egyéb pénztárgépek'!AG34 -> 0 | L22: =SUM(F22:I22) -> 0.5
B23: Egyéb | C23: AP A13608072
B24: Egyéb | C24: AP A13607772
B27: Összesen: | F27: =SUM(F3:F24) -> #REF! | G27: =SUM(G3:G24) -> #REF! | H27: =SUM(H3:H24) -> #REF! | I27: =SUM(I3:I24) -> #REF! | J27: 1495140 | L27: =SUM(L3:L24) -> #REF!

Sheet 202601
C2: AP kód | D2: Nyitó zárás | E2: Záró zárás | F2: 0 | G2: 0.05 | H2: 0.18 | I2: 0.27 | J2: kp | K2: bankkártya | L2: Időszak összes | M2: Göngy. forgalom | O2: kp | P2: bk
B3: Államkincstár | C3: =MÁK!A1 -> AP A13610440 | D3: 1009 | E3: 1029 | F3: =MÁK!C35 -> 17250 | G3: =MÁK!D35 -> 4328426 | H3: =MÁK!E35 -> 0.18 | I3: =MÁK!F35 -> 2825575.3 | J3: =MÁK!G35 -> 459515 | L3: =SUM(F3:I3) -> 7171251.5 | M3: 219216297 | O3: =J3+#REF! -> #REF! | P3: =SUM(L3:L3)-O3 -> #REF!
B5: Knorr105 | C5: =Knorr105!A1 -> AP A09111376 | D5: 428 | F5: =Knorr105!C$35 -> 19250 | G5: =Knorr105!D$35 -> 8487866 | H5: =Knorr105!E$35 -> 150 | I5: =Knorr105!F$35 -> 0 | J5: =Knorr105!G$35 -> 7190 | L5: =SUM(F5:I5) -> 8507266 | O5: =J5+J6+J7 -> 12405 | P5: =SUM(L5:L7)-O5 -> 14663802
B6: Knorr105 | C6: =Knorr105!Q1 -> AP A24010154 | D6: 384 | F6: =Knorr105!S$35 -> 57675 | G6: =Knorr105!T$35 -> 0.05 | H6: =Knorr105!U$35 -> 0.18 | I6: =Knorr105!V$35 -> 0.27 | J6: =Knorr105!W$35 -> 0 | L6: =SUM(F6:I6) -> 0.5
B7: Knorr105 | C7: =Knorr105!AG1 -> AP A13609805 | D7: 1239 | F7: =Knorr105!AI$35 -> 33940 | G7: =Knorr105!AJ$35 -> 7249299 | H7: =Knorr105!AK$35 -> 0.18 | I7: =Knorr105!AL$35 -> 50.27 | J7: =Knorr105!AM$35 -> 0 | L7: =SUM(F7:I7) -> 7283289.5
B8: Knorr105 | C8: AP A09110892 | D8: 990
B10: Knorr86 | C10: =Knorr86!A1 -> AP A13607465 | D10: 2274 | F10: =Knorr86!C34 -> 26950 | G10: =Knorr86!D34 -> 4767430 | H10: =Knorr86!E34 -> 0.18 | I10: =Knorr86!F34 -> 191365.27 | J10: =Knorr86!G34 -> 29890 | L10: =SUM(F10:I10) -> 4985745.5 | O10: =J10 -> 29890 | P10: =L10-O10 -> 4955855.5
B12: Knorr69 | C12: =Knorr69!A1 -> AP A09111377 | D12: 527 | F12: =Knorr69!#REF! -> #REF! | G12: =Knorr69!#REF! -> #REF! | H12: =Knorr69!#REF! -> #REF! | I12: =Knorr69!#REF! -> #REF! | J12: =Knorr69!#REF! -> #REF! | L12: =SUM(F12:I12) -> #REF! | M12: 134086437 | O12: =J12 -> #REF! | P12: =L12-O12 -> #REF!
B14: KTI | C14: =KTI!A1 -> AP A13607773 | D14: 1747 | F14: =KTI!#REF! -> #REF! | G14: =KTI!#REF! -> #REF! | H14: =KTI!#REF! -> #REF! | I14: =KTI!#REF! -> #REF! | J14: =KTI!#REF! -> #REF! | L14: =SUM(F14:I14) -> #REF! | O14: =J14 -> #REF! | P14: =L14-O14 -> #REF!
B16: Szentkirályi | C16: AP A13611447 | D16: 0041
B18: RSR | C18: AP A09111370 | D18: 0573 | F18: =RSR!C34 -> 4396 | G18: =RSR!D34 -> 17170.05 | H18: =RSR!E34 -> 58570.18 | I18: =RSR!F34 -> 907603.27 | J18: =RSR!G34 -> 318535 | L18: =SUM(F18:I18) -> 987739.5 | O18: =SUM(J18:J19) -> 434460 | P18: =SUM(L18:L19)-O18 -> 924222
B19: RSR | C19: AP A13610439 | D19: 0364 | F19: =RSR!S34 -> 550 | G19: =RSR!T34 -> 322492.05 | H19: =RSR!U34 -> 0.18 | I19: =RSR!V34 -> 47900.27 | J19: =RSR!W34 -> 115925 | L19: =SUM(F19:I19) -> 370942.5
B21: Egyéb (RSR) | C21: ='Egyéb pénztárgépek'!M1 -> AP A13609679 | F21: ='Egyéb pénztárgépek'!N34 -> 0 | G21: ='Egyéb pénztárgépek'!O34 -> 0.05 | H21: ='Egyéb pénztárgépek'!P34 -> 0.18 | I21: ='Egyéb pénztárgépek'!Q34 -> 0.27 | J21: ='Egyéb pénztárgépek'!R34 -> 0 | L21: =SUM(F21:I21) -> 0.5
B22: Egyéb (RSR) | C22: ='Egyéb pénztárgépek'!AB1 -> AP A09109974 | F22: ='Egyéb pénztárgépek'!AC34 -> 0 | G22: ='Egyéb pénztárgépek'!AD34 -> 0.05 | H22: ='Egyéb pénztárgépek'!AE34 -> 0.18 | I22: ='Egyéb pénztárgépek'!AF34 -> 0.27 | J22: ='Egyéb pénztárgépek'!AG34 -> 0 | L22: =SUM(F22:I22) -> 0.5
B23: Egyéb | C23: AP A13608072
B24: Egyéb | C24: AP A13607772 | D24: 2243
B27: Összesen: | F27: =SUM(F3:F24) -> #REF! | G27: =SUM(G3:G24) -> #REF! | H27: =SUM(H3:H24) -> #REF! | I27: =SUM(I3:I24) -> #REF! | J27: 1495140 | L27: =SUM(L3:L24) -> #REF!

Sheet MÁK
A1: AP A13610440 | B1: Novohost | C1: 0 | D1: 0.05 | E1: 0.18 | F1: 0.27 | G1: készpénz | H1: kártya | I1: terminál sz. bankkártya | J1: zárás sorszám | K1: göngyölt e. | L1: időszaki össz: | M1: EUR | N1: jegyzőkönyv | P1: Novohost
A2: Január | P2: ='[1]2026 január'!B1 -> Novohost | Q2: ='[1]2026 január'!G1 -> Tartalék kiadás | R2: ='[1]2026 január'!W1 -> Kivét | S2: Eredmény | V2: ='[1]2026 január'!S1 -> Pénztár nyitó | W2: ='[1]2026 január'!T1 -> novo kp bevétel | X2: ='[1]2026 január'!U1 -> Egyéb bevétel | Y2: ='[1]2026 január'!V1 -> Költött | Z2: ='[1]2026 január'!W1 -> Kivét | AA2: ='[1]2026 január'!X1 -> Eltérés | AB2: ='[1]2026 január'!Y1 -> Záró | AC2: ='[1]2026 január'!Z1 -> Megjegyzések | ... AG2: ='[1]2026 január'!AD1 -> 0
A3: 46023 | P3: =IF('[1]2026 január'!B$2=0, "", '[1]2026 január'!B$2 ) | Q3: =IF(OR('[1]2026 január'!G2=0, ISBLANK('[1]2026 január'!G2)), "", '[1]2026 január'!G2 ) | R3: ='[1]2026 január'!W2 -> 0 | S3: =P3-Q3-R3-G3-H3 -> #VALUE! | V3: =IF('[1]2026 január'!S2=0, "", '[1]2026 január'!S2 ) | W3: =IF('[1]2026 január'!T2=0, "", '[1]2026 január'!T2 ) | X3: =IF('[1]2026 január'!U2=0, "", '[1]2026 január'!U2 ) | Y3: =IF('[1]2026 január'!V2=0, "", '[1]2026 január'!V2 ) | Z3: =IF('[1]2026 január'!W2=0, "", '[1]2026 január'!W2 ) | AA3: =IF('[1]2026 január'!X2=0, "", '[1]2026 január'!X2 ) | AB3: =IF('[1]2026 január'!Y2=0, "", '[1]2026 január'!Y2 ) | AC3: =IF('[1]2026 január'!Z2=0, "", '[1]2026 január'!Z2 ) | AD3: =IF('[1]2026 január'!AA2=0, "", '[1]2026 január'!AA2 ) | AE3: =IF('[1]2026 január'!AB$2=0, "", '[1]2026 január'!AB$2 ) | AF3: =IF('[1]2026 január'!AC$2=0, "", '[1]2026 január'!AC$2 ) | AG3: =IF('[1]2026 január'!AD$2=0, "", '[1]2026 január'!AD$2 ) | AH3: =IF('[1]2026 január'!AE2=0, "", '[1]2026 január'!AE2 ) | AI3: =IF('[1]2026 január'!AF2=0, "", '[1]2026 január'!AF2 ) | AJ3: =IF('[1]2026 január'!AG2=0, "", '[1]2026 január'!AG2 ) | AK3: =IF('[1]2026 január'!AH2=0, "", '[1]2026 január'!AH2 )
A4: 46024 | P4: =IF('[1]2026 január'!B$3=0, "", '[1]2026 január'!B$3 ) | Q4: =IF(OR('[1]2026 január'!G3=0, ISBLANK('[1]2026 január'!G3)), "", '[1]2026 január'!G3 ) | R4: ='[1]2026 január'!W3 -> 0 | V4: =IF('[1]2026 január'!S3=0, "", '[1]2026 január'!S3 ) | W4: =IF('[1]2026 január'!T3=0, "", '[1]2026 január'!T3 ) | X4: =IF('[1]2026 január'!U3=0, "", '[1]2026 január'!U3 ) | Y4: =IF('[1]2026 január'!V3=0, "", '[1]2026 január'!V3 ) | Z4: =IF('[1]2026 január'!W3=0, "", '[1]2026 január'!W3 ) | AA4: =IF('[1]2026 január'!X3=0, "", '[1]2026 január'!X3 ) | AB4: =IF('[1]2026 január'!Y3=0, "", '[1]2026 január'!Y3 ) | AC4: =IF('[1]2026 január'!Z3=0, "", '[1]2026 január'!Z3 ) | AD4: =IF('[1]2026 január'!AA3=0, "", '[1]2026 január'!AA3 ) | AE4: =IF('[1]2026 január'!AB$3=0, "", '[1]2026 január'!AB$3 ) | AF4: =IF('[1]2026 január'!AC$3=0, "", '[1]2026 január'!AC$3 ) | AG4: =IF('[1]2026 január'!AD$3=0, "", '[1]2026 január'!AD$3 ) | AH4: =IF('[1]2026 január'!AE3=0, "", '[1]2026 január'!AE3 ) | AI4: =IF('[1]2026 január'!AF3=0, "", '[1]2026 január'!AF3 ) | AJ4: =IF('[1]2026 január'!AG3=0, "", '[1]2026 január'!AG3 ) | AK4: =IF('[1]2026 január'!AH3=0, "", '[1]2026 január'!AH3 )
A5: 46025 | P5: =IF('[1]2026 január'!B$4=0, "", '[1]2026 január'!B$4 ) | Q5: =IF(OR('[1]2026 január'!G4=0, ISBLANK('[1]2026 január'!G4)), "", '[1]2026 január'!G4 ) | R5: ='[1]2026 január'!W4 -> 0 | V5: =IF('[1]2026 január'!S4=0, "", '[1]2026 január'!S4 ) | W5: =IF('[1]2026 január'!T4=0, "", '[1]2026 január'!T4 ) | X5: =IF('[1]2026 január'!U4=0, "", '[1]2026 január'!U4 ) | Y5: =IF('[1]2026 január'!V4=0, "", '[1]2026 január'!V4 ) | Z5: =IF('[1]2026 január'!W4=0, "", '[1]2026 január'!W4 ) | AA5: =IF('[1]2026 január'!X4=0, "", '[1]2026 január'!X4 ) | AB5: =IF('[1]2026 január'!Y4=0, "", '[1]2026 január'!Y4 ) | AC5: =IF('[1]2026 január'!Z4=0, "", '[1]2026 január'!Z4 ) | AD5: =IF('[1]2026 január'!AA4=0, "", '[1]2026 január'!AA4 ) | AE5: =IF('[1]2026 január'!AB$4=0, "", '[1]2026 január'!AB$4 ) | AF5: =IF('[1]2026 január'!AC$4=0, "", '[1]2026 január'!AC$4 ) | AG5: =IF('[1]2026 január'!AD$4=0, "", '[1]2026 január'!AD$4 ) | AH5: =IF('[1]2026 január'!AE4=0, "", '[1]2026 január'!AE4 ) | AI5: =IF('[1]2026 január'!AF4=0, "", '[1]2026 január'!AF4 ) | AJ5: =IF('[1]2026 január'!AG4=0, "", '[1]2026 január'!AG4 ) | AK5: =IF('[1]2026 január'!AH4=0, "", '[1]2026 január'!AH4 )
A6: 46026
A7: 46027 | C7: 1150 | D7: 164389 | F7: 177841 | G7: 33775 | H7: 309605 | I7: 314305 | J7: 1009 | K7: 212688426 | P7: =IF('[1]2026 január'!B$5=0, "", '[1]2026 január'!B$5 ) | Q7: =IF(OR('[1]2026 január'!G5=0, ISBLANK('[1]2026 január'!G5)), "", '[1]2026 január'!G5 ) | R7: ='[1]2026 január'!W5 -> 0 | V7: =IF('[1]2026 január'!S5=0, "", '[1]2026 január'!S5 ) | W7: =IF('[1]2026 január'!T5=0, "", '[1]2026 január'!T5 ) | X7: =IF('[1]2026 január'!U5=0, "", '[1]2026 január'!U5 ) | Y7: =IF('[1]2026 január'!V5=0, "", '[1]2026 január'!V5 ) | Z7: =IF('[1]2026 január'!W5=0, "", '[1]2026 január'!W5 ) | AA7: =IF('[1]2026 január'!X5=0, "", '[1]2026 január'!X5 ) | AB7: =IF('[1]2026 január'!Y5=0, "", '[1]2026 január'!Y5 ) | AC7: =IF('[1]2026 január'!Z5=0, "", '[1]2026 január'!Z5 ) | AD7: =IF('[1]2026 január'!AA5=0, "", '[1]2026 január'!AA5 ) | AE7: =IF('[1]2026 január'!AB$5=0, "", '[1]2026 január'!AB$5 ) | AF7: =IF('[1]2026 január'!AC$5=0, "", '[1]2026 január'!AC$5 ) | AG7: =IF('[1]2026 január'!AD$5=0, "", '[1]2026 január'!AD$5 ) | AH7: =IF('[1]2026 január'!AE5=0, "", '[1]2026 január'!AE5 ) | AI7: =IF('[1]2026 január'!AF5=0, "", '[1]2026 január'!AF5 ) | AJ7: =IF('[1]2026 január'!AG5=0, "", '[1]2026 január'!AG5 ) | AK7: =IF('[1]2026 január'!AH5=0, "", '[1]2026 január'!AH5 )
A8: 46027 | B8: 366030 | F8: 4700 | H8: 4700 | J8: 1010 | K8: 212693126 | P8: =IF('[1]2026 január'!B$6=0, "", '[1]2026 január'!B$6 ) -> 348080 | Q8: =IF(OR('[1]2026 január'!G6=0, ISBLANK('[1]2026 január'!G6)), "", '[1]2026 január'!G6 ) | R8: ='[1]2026 január'!W6 -> 0 | V8: =IF('[1]2026 január'!S6=0, "", '[1]2026 január'!S6 ) -> 119577 | W8: =IF('[1]2026 január'!T6=0, "", '[1]2026 január'!T6 ) -> 33775 | X8: =IF('[1]2026 január'!U6=0, "", '[1]2026 január'!U6 ) | Y8: =IF('[1]2026 január'!V6=0, "", '[1]2026 január'!V6 ) | Z8: =IF('[1]2026 január'!W6=0, "", '[1]2026 január'!W6 ) | AA8: =IF('[1]2026 január'!X6=0, "", '[1]2026 január'!X6 ) | AB8: =IF('[1]2026 január'!Y6=0, "", '[1]2026 január'!Y6 ) -> 153352 | AC8: =IF('[1]2026 január'!Z6=0, "", '[1]2026 január'!Z6 ) | AD8: =IF('[1]2026 január'!AA6=0, "", '[1]2026 január'!AA6 ) | AE8: =IF('[1]2026 január'!AB$6=0, "", '[1]2026 január'!AB$6 ) | AF8: =IF('[1]2026 január'!AC$6=0, "", '[1]2026 január'!AC$6 ) | AG8: =IF('[1]2026 január'!AD$6=0, "", '[1]2026 január'!AD$6 ) | AH8: =IF('[1]2026 január'!AE6=0, "", '[1]2026 január'!AE6 ) | AI8: =IF('[1]2026 január'!AF6=0, "", '[1]2026 január'!AF6 ) | AJ8: =IF('[1]2026 január'!AG6=0, "", '[1]2026 január'!AG6 ) | AK8: =IF('[1]2026 január'!AH6=0, "", '[1]2026 január'!AH6 )
A9: 46028 | B9: 412300 | C9: 750 | D9: 242410 | F9: 199650 | G9: 16720 | H9: 426090 | I9: 426090 | J9: 1011 | K9: 213135936 | P9: =IF('[1]2026 január'!B$7=0, "", '[1]2026 január'!B$7 ) -> 402810 | Q9: =IF(OR('[1]2026 január'!G7=0, ISBLANK('[1]2026 január'!G7)), "", '[1]2026 január'!G7 ) | R9: ='[1]2026 január'!W7 -> 0 | V9: =IF('[1]2026 január'!S7=0, "", '[1]2026 január'!S7 ) -> 153352 | W9: =IF('[1]2026 január'!T7=0, "", '[1]2026 január'!T7 ) -> -23280 | X9: =IF('[1]2026 január'!U7=0, "", '[1]2026 január'!U7 ) -> 44985 | Y9: =IF('[1]2026 január'!V7=0, "", '[1]2026 január'!V7 ) -> 3600 | Z9: =IF('[1]2026 január'!W7=0, "", '[1]2026 január'!W7 ) | AA9: =IF('[1]2026 január'!X7=0, "", '[1]2026 január'!X7 ) | AB9: =IF('[1]2026 január'!Y7=0, "", '[1]2026 január'!Y7 ) -> 171457 | AC9: =IF('[1]2026 január'!Z7=0, "", '[1]2026 január'!Z7 ) | AD9: =IF('[1]2026 január'!AA7=0, "", '[1]2026 január'!AA7 ) -> Vásárlás | AE9: =IF('[1]2026 január'!AB$7=0, "", '[1]2026 január'!AB$7 ) -> Vip töltés | AF9: =IF('[1]2026 január'!AC$7=0, "", '[1]2026 január'!AC$7 ) | AG9: =IF('[1]2026 január'!AD$7=0, "", '[1]2026 január'!AD$7 ) | AH9: =IF('[1]2026 január'!AE7=0, "", '[1]2026 január'!AE7 ) | AI9: =IF('[1]2026 január'!AF7=0, "", '[1]2026 január'!AF7 ) | AJ9: =IF('[1]2026 január'!AG7=0, "", '[1]2026 január'!AG7 ) | AK9: =IF('[1]2026 január'!AH7=0, "", '[1]2026 január'!AH7 )
A10: 46029 | B10: 423525 | C10: 850 | D10: 247930 | F10: 161945 | G10: 20510 | H10: 390215 | I10: 390215 | J10: 1012 | K10: 213546661 | P10: =IF('[1]2026 január'!B$8=0, "", '[1]2026 január'!B$8 ) -> 410725 | Q10: =IF(OR('[1]2026 január'!G8=0, ISBLANK('[1]2026 január'!G8)), "", '[1]2026 január'!G8 ) | R10: ='[1]2026 január'!W8 -> 7190 | V10: =IF('[1]2026 január'!S8=0, "", '[1]2026 január'!S8 ) -> 171457 | W10: =IF('[1]2026 január'!T8=0, "", '[1]2026 január'!T8 ) -> 20510 | X10: =IF('[1]2026 január'!U8=0, "", '[1]2026 január'!U8 ) | Y10: =IF('[1]2026 január'!V8=0, "", '[1]2026 január'!V8 ) | Z10: =IF('[1]2026 január'!W8=0, "", '[1]2026 január'!W8 ) -> 7190 | AA10: =IF('[1]2026 január'!X8=0, "", '[1]2026 január'!X8 ) | AB10: =IF('[1]2026 január'!Y8=0, "", '[1]2026 január'!Y8 ) -> 184777 | AC10: =IF('[1]2026 január'!Z8=0, "", '[1]2026 január'!Z8 ) | AD10: =IF('[1]2026 január'!AA8=0, "", '[1]2026 január'!AA8 ) -> Matrica | AE10: =IF('[1]2026 január'!AB$8=0, "", '[1]2026 január'!AB$8 ) | AF10: =IF('[1]2026 január'!AC$8=0, "", '[1]2026 január'!AC$8 ) | AG10: =IF('[1]2026 január'!AD$8=0, "", '[1]2026 január'!AD$8 ) | AH10: =IF('[1]2026 január'!AE8=0, "", '[1]2026 január'!AE8 ) | AI10: =IF('[1]2026 január'!AF8=0, "", '[1]2026 január'!AF8 ) | AJ10: =IF('[1]2026 január'!AG8=0, "", '[1]2026 január'!AG8 ) | AK10: =IF('[1]2026 január'!AH8=0, "", '[1]2026 január'!AH8 )
A11: 46030 | B11: 459800 | C11: 1150 | D11: 275605 | F11: 196505 | G11: 28825 | H11: 444435 | I11: 444435 | J11: 1013 | K11: 214019921 | P11: =IF('[1]2026 január'!B$9=0, "", '[1]2026 január'!B$9 ) -> 443260 | Q11: =IF(OR('[1]2026 január'!G9=0, ISBLANK('[1]2026 január'!G9)), "", '[1]2026 január'!G9 ) | R11: ='[1]2026 január'!W9 -> 0 | V11: =IF('[1]2026 január'!S9=0, "", '[1]2026 január'!S9 ) -> 184777 | W11: =IF('[1]2026 január'!T9=0, "", '[1]2026 január'!T9 ) -> -1175 | X11: =IF('[1]2026 január'!U9=0, "", '[1]2026 január'!U9 ) | Y11: =IF('[1]2026 január'!V9=0, "", '[1]2026 január'!V9 ) -> 22997 | Z11: =IF('[1]2026 január'!W9=0, "", '[1]2026 január'!W9 ) | AA11: =IF('[1]2026 január'!X9=0, "", '[1]2026 január'!X9 ) | AB11: =IF('[1]2026 január'!Y9=0, "", '[1]2026 január'!Y9 ) -> 160605 | AC11: =IF('[1]2026 január'!Z9=0, "", '[1]2026 január'!Z9 ) | AD11: =IF('[1]2026 január'!AA9=0, "", '[1]2026 január'!AA9 ) -> Media Markt | AE11: =IF('[1]2026 január'!AB$9=0, "", '[1]2026 január'!AB$9 ) | AF11: =IF('[1]2026 január'!AC$9=0, "", '[1]2026 január'!AC$9 ) | AG11: =IF('[1]2026 január'!AD$9=0, "", '[1]2026 január'!AD$9 ) | AH11: =IF('[1]2026 január'!AE9=0, "", '[1]2026 január'!AE9 ) | AI11: =IF('[1]2026 január'!AF9=0, "", '[1]2026 január'!AF9 ) | AJ11: =IF('[1]2026 január'!AG9=0, "", '[1]2026 január'!AG9 ) | AK11: =IF('[1]2026 január'!AH9=0, "", '[1]2026 január'!AH9 )
A12: 46031 | B12: 377780 | C12: 700 | D12: 301850 | F12: 108675 | G12: 12365 | H12: 398860 | I12: 398860 | J12: 1014 | K12: 214431146 | P12: =IF('[1]2026 január'!B$10=0, "", '[1]2026 január'!B$10 ) -> 361225 | Q12: =IF(OR('[1]2026 január'!G10=0, ISBLANK('[1]2026 január'!G10)), "", '[1]2026 január'!G10 ) | R12: ='[1]2026 január'!W10 -> 0 | V12: =IF('[1]2026 január'!S10=0, "", '[1]2026 január'!S10 ) -> 160605 | W12: =IF('[1]2026 január'!T10=0, "", '[1]2026 január'!T10 ) -> -37735 | X12: =IF('[1]2026 január'!U10=0, "", '[1]2026 január'!U10 ) -> 104000 | Y12: =IF('[1]2026 január'!V10=0, "", '[1]2026 január'!V10 ) -> 79850 | Z12: =IF('[1]2026 január'!W10=0, "", '[1]2026 január'!W10 ) | AA12: =IF('[1]2026 január'!X10=0, "", '[1]2026 január'!X10 ) | AB12: =IF('[1]2026 január'!Y10=0, "", '[1]2026 január'!Y10 ) -> 147020 | AC12: =IF('[1]2026 január'!Z10=0, "", '[1]2026 január'!Z10 ) | AD12: =IF('[1]2026 január'!AA10=0, "", '[1]2026 január'!AA10 ) -> Vásárlás, Vip töltés, Melinda, Parkolás | AE12: =IF('[1]2026 január'!AB$10=0, "", '[1]2026 január'!AB$10 ) | AF12: =IF('[1]2026 január'!AC$10=0, "", '[1]2026 január'!AC$10 ) | AG12: =IF('[1]2026 január'!AD$10=0, "", '[1]2026 január'!AD$10 ) | AH12: =IF('[1]2026 január'!AE10=0, "", '[1]2026 január'!AE10 ) | AI12: =IF('[1]2026 január'!AF10=0, "", '[1]2026 január'!AF10 ) | AJ12: =IF('[1]2026 január'!AG10=0, "", '[1]2026 január'!AG10 ) | AK12: =IF('[1]2026 január'!AH10=0, "", '[1]2026 január'!AH10 )
A13: 46032 | P13: =IF('[1]2026 január'!B$11=0, "", '[1]2026 január'!B$11 ) | Q13: =IF(OR('[1]2026 január'!G11=0, ISBLANK('[1]2026 január'!G11)), "", '[1]2026 január'!G11 ) | R13: ='[1]2026 január'!W11 -> 0 | V13: =IF('[1]2026 január'!S11=0, "", '[1]2026 január'!S11 ) -> 147020 | W13: =IF('[1]2026 január'!T11=0, "", '[1]2026 január'!T11 ) | X13: =IF('[1]2026 január'!U11=0, "", '[1]2026 január'!U11 ) | Y13: =IF('[1]2026 január'!V11=0, "", '[1]2026 január'!V11 ) | Z13: =IF('[1]2026 január'!W11=0, "", '[1]2026 január'!W11 ) | AA13: =IF('[1]2026 január'!X11=0, "", '[1]2026 január'!X11 ) | AB13: =IF('[1]2026 január'!Y11=0, "", '[1]2026 január'!Y11 ) -> 147020 | AC13: =IF('[1]2026 január'!Z11=0, "", '[1]2026 január'!Z11 ) | AD13: =IF('[1]2026 január'!AA11=0, "", '[1]2026 január'!AA11 ) | AE13: =IF('[1]2026 január'!AB$11=0, "", '[1]2026 január'!AB$11 ) | AF13: =IF('[1]2026 január'!AC$11=0, "", '[1]2026 január'!AC$11 ) | AG13: =IF('[1]2026 január'!AD$11=0, "", '[1]2026 január'!AD$11 ) | AH13: =IF('[1]2026 január'!AE11=0, "", '[1]2026 január'!AE11 ) | AI13: =IF('[1]2026 január'!AF11=0, "", '[1]2026 január'!AF11 ) | AJ13: =IF('[1]2026 január'!AG11=0, "", '[1]2026 január'!AG11 ) | AK13: =IF('[1]2026 január'!AH11=0, "", '[1]2026 január'!AH11 )
A14: 46033 | P14: =IF('[1]2026 január'!B$12=0, "", '[1]2026 január'!B$12 ) | Q14: =IF(OR('[1]2026 január'!G12=0, ISBLANK('[1]2026 január'!G12)), "", '[1]2026 január'!G12 ) | R14: ='[1]2026 január'!W12 -> 0 | V14: =IF('[1]2026 január'!S12=0, "", '[1]2026 január'!S12 ) -> 147020 | W14: =IF('[1]2026 január'!T12=0, "", '[1]2026 január'!T12 ) | X14: =IF('[1]2026 január'!U12=0, "", '[1]2026 január'!U12 ) | Y14: =IF('[1]2026 január'!V12=0, "", '[1]2026 január'!V12 ) | Z14: =IF('[1]2026 január'!W12=0, "", '[1]2026 január'!W12 ) | AA14: =IF('[1]2026 január'!X12=0, "", '[1]2026 január'!X12 ) | AB14: =IF('[1]2026 január'!Y12=0, "", '[1]2026 január'!Y12 ) -> 147020 | AC14: =IF('[1]2026 január'!Z12=0, "", '[1]2026 január'!Z12 ) | AD14: =IF('[1]2026 január'!AA12=0, "", '[1]2026 január'!AA12 ) | AE14: =IF('[1]2026 január'!AB$12=0, "", '[1]2026 január'!AB$12 ) | AF14: =IF('[1]2026 január'!AC$12=0, "", '[1]2026 január'!AC$12 ) | AG14: =IF('[1]2026 január'!AD$12=0, "", '[1]2026 január'!AD$12 ) | AH14: =IF('[1]2026 január'!AE12=0, "", '[1]2026 január'!AE12 ) | AI14: =IF('[1]2026 január'!AF12=0, "", '[1]2026 január'!AF12 ) | AJ14: =IF('[1]2026 január'!AG12=0, "", '[1]2026 január'!AG12 ) | AK14: =IF('[1]2026 január'!AH12=0, "", '[1]2026 január'!AH12 )
A15: 46034 | B15: 359915 | C15: 1000 | D15: 203450 | F15: 148695 | G15: 18725 | H15: 332630 | I15: 332630 | J15: 1015 | K15: 214784291 | M15: 1790 | P15: =IF('[1]2026 január'!B$13=0, "", '[1]2026 január'!B$13 ) -> 351355 | Q15: =IF(OR('[1]2026 január'!G13=0, ISBLANK('[1]2026 január'!G13)), "", '[1]2026 január'!G13 ) | R15: ='[1]2026 január'!W13 -> 0 | V15: =IF('[1]2026 január'!S13=0, "", '[1]2026 január'!S13 ) -> 147020 | W15: =IF('[1]2026 január'!T13=0, "", '[1]2026 január'!T13 ) -> 18725 | X15: =IF('[1]2026 január'!U13=0, "", '[1]2026 január'!U13 ) | Y15: =IF('[1]2026 január'!V13=0, "", '[1]2026 január'!V13 ) | Z15: =IF('[1]2026 január'!W13=0, "", '[1]2026 január'!W13 ) | AA15: =IF('[1]2026 január'!X13=0, "", '[1]2026 január'!X13 ) | AB15: =IF('[1]2026 január'!Y13=0, "", '[1]2026 január'!Y13 ) -> 165745 | AC15: =IF('[1]2026 január'!Z13=0, "", '[1]2026 január'!Z13 ) | AD15: =IF('[1]2026 január'!AA13=0, "", '[1]2026 január'!AA13 ) | AE15: =IF('[1]2026 január'!AB$13=0, "", '[1]2026 január'!AB$13 ) | AF15: =IF('[1]2026 január'!AC$13=0, "", '[1]2026 január'!AC$13 ) | AG15: =IF('[1]2026 január'!AD$13=0, "", '[1]2026 január'!AD$13 ) | AH15: =IF('[1]2026 január'!AE13=0, "", '[1]2026 január'!AE13 ) | AI15: =IF('[1]2026 január'!AF13=0, "", '[1]2026 január'!AF13 ) | AJ15: =IF('[1]2026 január'!AG13=0, "", '[1]2026 január'!AG13 ) | AK15: =IF('[1]2026 január'!AH13=0, "", '[1]2026 január'!AH13 )
A16: 46035 | B16: 479540 | C16: 950 | D16: 312260 | F16: 153045 | G16: 23625 | H16: 442630 | I16: 442630 | J16: 1016 | K16: 215250546 | P16: =IF('[1]2026 január'!B$14=0, "", '[1]2026 január'!B$14 ) -> 466255 | Q16: =IF(OR('[1]2026 január'!G14=0, ISBLANK('[1]2026 január'!G14)), "", '[1]2026 január'!G14 ) | R16: ='[1]2026 január'!W14 -> 0 | V16: =IF('[1]2026 január'!S14=0, "", '[1]2026 január'!S14 ) -> 165745 | W16: =IF('[1]2026 január'!T14=0, "", '[1]2026 január'!T14 ) -> 23625 | X16: =IF('[1]2026 január'!U14=0, "", '[1]2026 január'!U14 ) | Y16: =IF('[1]2026 január'!V14=0, "", '[1]2026 január'!V14 ) | Z16: =IF('[1]2026 január'!W14=0, "", '[1]2026 január'!W14 ) | AA16: =IF('[1]2026 január'!X14=0, "", '[1]2026 január'!X14 ) | AB16: =IF('[1]2026 január'!Y14=0, "", '[1]2026 január'!Y14 ) -> 189370 | AC16: =IF('[1]2026 január'!Z14=0, "", '[1]2026 január'!Z14 ) | AD16: =IF('[1]2026 január'!AA14=0, "", '[1]2026 január'!AA14 ) | AE16: =IF('[1]2026 január'!AB$14=0, "", '[1]2026 január'!AB$14 ) | AF16: =IF('[1]2026 január'!AC$14=0, "", '[1]2026 január'!AC$14 ) | AG16: =IF('[1]2026 január'!AD$14=0, "", '[1]2026 január'!AD$14 ) | AH16: =IF('[1]2026 január'!AE14=0, "", '[1]2026 január'!AE14 ) | AI16: =IF('[1]2026 január'!AF14=0, "", '[1]2026 január'!AF14 ) | AJ16: =IF('[1]2026 január'!AG14=0, "", '[1]2026 január'!AG14 ) | AK16: =IF('[1]2026 január'!AH14=0, "", '[1]2026 január'!AH14 )
A17: 46036 | B17: 363510 | C17: 700 | D17: 240091 | F17: 110000 | G17: 20045 | H17: 330745 | I17: 371745 | J17: 1017 | K17: 215601337 | P17: =IF('[1]2026 január'!B$15=0, "", '[1]2026 január'!B$15 ) -> 350790 | Q17: =IF(OR('[1]2026 január'!G15=0, ISBLANK('[1]2026 január'!G15)), "", '[1]2026 január'!G15 ) | R17: ='[1]2026 január'!W15 -> 0 | V17: =IF('[1]2026 január'!S15=0, "", '[1]2026 január'!S15 ) -> 189370 | W17: =IF('[1]2026 január'!T15=0, "", '[1]2026 január'!T15 ) -> -20955 | X17: =IF('[1]2026 január'!U15=0, "", '[1]2026 január'!U15 ) -> 41000 | Y17: =IF('[1]2026 január'!V15=0, "", '[1]2026 január'!V15 ) -> 63000 | Z17: =IF('[1]2026 január'!W15=0, "", '[1]2026 január'!W15 ) | AA17: =IF('[1]2026 január'!X15=0, "", '[1]2026 január'!X15 ) | AB17: =IF('[1]2026 január'!Y15=0, "", '[1]2026 január'!Y15 ) -> 146415 | AC17: =IF('[1]2026 január'!Z15=0, "", '[1]2026 január'!Z15 ) | AD17: =IF('[1]2026 január'!AA15=0, "", '[1]2026 január'!AA15 ) -> Márk, Vip töltés | AE17: =IF('[1]2026 január'!AB$15=0, "", '[1]2026 január'!AB$15 ) | AF17: =IF('[1]2026 január'!AC$15=0, "", '[1]2026 január'!AC$15 ) | AG17: =IF('[1]2026 január'!AD$15=0, "", '[1]2026 január'!AD$15 ) | AH17: =IF('[1]2026 január'!AE15=0, "", '[1]2026 január'!AE15 ) | AI17: =IF('[1]2026 január'!AF15=0, "", '[1]2026 január'!AF15 ) | AJ17: =IF('[1]2026 január'!AG15=0, "", '[1]2026 január'!AG15 ) | AK17: =IF('[1]2026 január'!AH15=0, "", '[1]2026 január'!AH15 )
A18: 46037 | B18: 335270 | C18: 800 | D18: 245235 | F18: 107715 | G18: 27940 | H18: 325810 | I18: 325810 | J18: 1018 | K18: 215955087 | P18: =IF('[1]2026 január'!B$16=0, "", '[1]2026 január'!B$16 ) -> 323750 | Q18: =IF(OR('[1]2026 január'!G16=0, ISBLANK('[1]2026 január'!G16)), "", '[1]2026 január'!G16 ) | R18: ='[1]2026 január'!W16 -> 0 | V18: =IF('[1]2026 január'!S16=0, "", '[1]2026 január'!S16 ) -> 146415 | W18: =IF('[1]2026 január'!T16=0, "", '[1]2026 január'!T16 ) -> -2060 | X18: =IF('[1]2026 január'!U16=0, "", '[1]2026 január'!U16 ) -> 30000 | Y18: =IF('[1]2026 január'!V16=0, "", '[1]2026 január'!V16 ) | Z18: =IF('[1]2026 január'!W16=0, "", '[1]2026 január'!W16 ) | AA18: =IF('[1]2026 január'!X16=0, "", '[1]2026 január'!X16 ) | AB18: =IF('[1]2026 január'!Y16=0, "", '[1]2026 január'!Y16 ) -> 174355 | AC18: =IF('[1]2026 január'!Z16=0, "", '[1]2026 január'!Z16 ) | AD18: =IF('[1]2026 január'!AA16=0, "", '[1]2026 január'!AA16 ) -> Vip töltés | AE18: =IF('[1]2026 január'!AB$16=0, "", '[1]2026 január'!AB$16 ) | AF18: =IF('[1]2026 január'!AC$16=0, "", '[1]2026 január'!AC$16 ) | AG18: =IF('[1]2026 január'!AD$16=0, "", '[1]2026 január'!AD$16 ) | AH18: =IF('[1]2026 január'!AE16=0, "", '[1]2026 január'!AE16 ) | AI18: =IF('[1]2026 január'!AF16=0, "", '[1]2026 január'!AF16 ) | AJ18: =IF('[1]2026 január'!AG16=0, "", '[1]2026 január'!AG16 ) | AK18: =IF('[1]2026 január'!AH16=0, "", '[1]2026 január'!AH16 )
A19: 46038 | B19: 284595 | C19: 550 | D19: 160155 | F19: 120070 | G19: 24505 | H19: 256270 | I19: 256270 | J19: 1019 | K19: 216235862 | P19: =IF('[1]2026 január'!B$17=0, "", '[1]2026 január'!B$17 ) -> 280775 | Q19: =IF(OR('[1]2026 január'!G17=0, ISBLANK('[1]2026 január'!G17)), "", '[1]2026 január'!G17 ) | R19: ='[1]2026 január'!W17 -> 0 | V19: =IF('[1]2026 január'!S17=0, "", '[1]2026 január'!S17 ) -> 174355 | W19: =IF('[1]2026 január'!T17=0, "", '[1]2026 január'!T17 ) -> 24505 | X19: =IF('[1]2026 január'!U17=0, "", '[1]2026 január'!U17 ) | Y19: =IF('[1]2026 január'!V17=0, "", '[1]2026 január'!V17 ) -> 99015 | Z19: =IF('[1]2026 január'!W17=0, "", '[1]2026 január'!W17 ) | AA19: =IF('[1]2026 január'!X17=0, "", '[1]2026 január'!X17 ) | AB19: =IF('[1]2026 január'!Y17=0, "", '[1]2026 január'!Y17 ) -> 99845 | AC19: =IF('[1]2026 január'!Z17=0, "", '[1]2026 január'!Z17 ) | AD19: =IF('[1]2026 január'!AA17=0, "", '[1]2026 január'!AA17 ) -> Melinda | AE19: =IF('[1]2026 január'!AB$17=0, "", '[1]2026 január'!AB$17 ) | AF19: =IF('[1]2026 január'!AC$17=0, "", '[1]2026 január'!AC$17 ) | AG19: =IF('[1]2026 január'!AD$17=0, "", '[1]2026 január'!AD$17 ) | AH19: =IF('[1]2026 január'!AE17=0, "", '[1]2026 január'!AE17 ) | AI19: =IF('[1]2026 január'!AF17=0, "", '[1]2026 január'!AF17 ) | AJ19: =IF('[1]2026 január'!AG17=0, "", '[1]2026 január'!AG17 ) | AK19: =IF('[1]2026 január'!AH17=0, "", '[1]2026 január'!AH17 )
A20: 46039 | P20: =IF('[1]2026 január'!B$18=0, "", '[1]2026 január'!B$18 ) | Q20: =IF(OR('[1]2026 január'!G18=0, ISBLANK('[1]2026 január'!G18)), "", '[1]2026 január'!G18 ) | R20: ='[1]2026 január'!W18 -> 0 | V20: =IF('[1]2026 január'!S18=0, "", '[1]2026 január'!S18 ) -> 99845 | W20: =IF('[1]2026 január'!T18=0, "", '[1]2026 január'!T18 ) | X20: =IF('[1]2026 január'!U18=0, "", '[1]2026 január'!U18 ) | Y20: =IF('[1]2026 január'!V18=0, "", '[1]2026 január'!V18 ) | Z20: =IF('[1]2026 január'!W18=0, "", '[1]2026 január'!W18 ) | AA20: =IF('[1]2026 január'!X18=0, "", '[1]2026 január'!X18 ) | AB20: =IF('[1]2026 január'!Y18=0, "", '[1]2026 január'!Y18 ) -> 99845 | AC20: =IF('[1]2026 január'!Z18=0, "", '[1]2026 január'!Z18 ) | AD20: =IF('[1]2026 január'!AA18=0, "", '[1]2026 január'!AA18 ) | AE20: =IF('[1]2026 január'!AB$18=0, "", '[1]2026 január'!AB$18 ) | AF20: =IF('[1]2026 január'!AC$18=0, "", '[1]2026 január'!AC$18 ) | AG20: =IF('[1]2026 január'!AD$18=0, "", '[1]2026 január'!AD$18 ) | AH20: =IF('[1]2026 január'!AE18=0, "", '[1]2026 január'!AE18 ) | AI20: =IF('[1]2026 január'!AF18=0, "", '[1]2026 január'!AF18 ) | AJ20: =IF('[1]2026 január'!AG18=0, "", '[1]2026 január'!AG18 ) | AK20: =IF('[1]2026 január'!AH18=0, "", '[1]2026 január'!AH18 )
A21: 46040 | P21: =IF('[1]2026 január'!B$19=0, "", '[1]2026 január'!B$19 ) | Q21: =IF(OR('[1]2026 január'!G19=0, ISBLANK('[1]2026 január'!G19)), "", '[1]2026 január'!G19 ) | R21: ='[1]2026 január'!W19 -> 0 | V21: =IF('[1]2026 január'!S19=0, "", '[1]2026 január'!S19 ) -> 99845 | W21: =IF('[1]2026 január'!T19=0, "", '[1]2026 január'!T19 ) | X21: =IF('[1]2026 január'!U19=0, "", '[1]2026 január'!U19 ) | Y21: =IF('[1]2026 január'!V19=0, "", '[1]2026 január'!V19 ) | Z21: =IF('[1]2026 január'!W19=0, "", '[1]2026 január'!W19 ) | AA21: =IF('[1]2026 január'!X19=0, "", '[1]2026 január'!X19 ) | AB21: =IF('[1]2026 január'!Y19=0, "", '[1]2026 január'!Y19 ) -> 99845 | AC21: =IF('[1]2026 január'!Z19=0, "", '[1]2026 január'!Z19 ) | AD21: =IF('[1]2026 január'!AA19=0, "", '[1]2026 január'!AA19 ) | AE21: =IF('[1]2026 január'!AB$19=0, "", '[1]2026 január'!AB$19 ) | AF21: =IF('[1]2026 január'!AC$19=0, "", '[1]2026 január'!AC$19 ) | AG21: =IF('[1]2026 január'!AD$19=0, "", '[1]2026 január'!AD$19 ) | AH21: =IF('[1]2026 január'!AE19=0, "", '[1]2026 január'!AE19 ) | AI21: =IF('[1]2026 január'!AF19=0, "", '[1]2026 január'!AF19 ) | AJ21: =IF('[1]2026 január'!AG19=0, "", '[1]2026 január'!AG19 ) | AK21: =IF('[1]2026 január'!AH19=0, "", '[1]2026 január'!AH19 )
A22: 46041 | B22: 311770 | C22: 650 | D22: 139715 | F22: 154705 | G22: 24775 | H22: 270295 | I22: 270295 | J22: 1020 | K22: 216530932 | P22: =IF('[1]2026 január'!B$20=0, "", '[1]2026 január'!B$20 ) -> 295070 | Q22: =IF(OR('[1]2026 január'!G20=0, ISBLANK('[1]2026 január'!G20)), "", '[1]2026 január'!G20 ) | R22: ='[1]2026 január'!W20 -> 0 | V22: =IF('[1]2026 január'!S20=0, "", '[1]2026 január'!S20 ) -> 99845 | W22: =IF('[1]2026 január'!T20=0, "", '[1]2026 január'!T20 ) -> 24775 | X22: =IF('[1]2026 január'!U20=0, "", '[1]2026 január'!U20 ) | Y22: =IF('[1]2026 január'!V20=0, "", '[1]2026 január'!V20 ) | Z22: =IF('[1]2026 január'!W20=0, "", '[1]2026 január'!W20 ) | AA22: =IF('[1]2026 január'!X20=0, "", '[1]2026 január'!X20 ) | AB22: =IF('[1]2026 január'!Y20=0, "", '[1]2026 január'!Y20 ) -> 124620 | AC22: =IF('[1]2026 január'!Z20=0, "", '[1]2026 január'!Z20 ) | AD22: =IF('[1]2026 január'!AA20=0, "", '[1]2026 január'!AA20 ) | AE22: =IF('[1]2026 január'!AB$20=0, "", '[1]2026 január'!AB$20 ) | AF22: =IF('[1]2026 január'!AC$20=0, "", '[1]2026 január'!AC$20 ) | AG22: =IF('[1]2026 január'!AD$20=0, "", '[1]2026 január'!AD$20 ) | AH22: =IF('[1]2026 január'!AE20=0, "", '[1]2026 január'!AE20 ) | AI22: =IF('[1]2026 január'!AF20=0, "", '[1]2026 január'!AF20 ) | AJ22: =IF('[1]2026 január'!AG20=0, "", '[1]2026 január'!AG20 ) | AK22: =IF('[1]2026 január'!AH20=0, "", '[1]2026 január'!AH20 )
A23: 46042 | B23: 401625 | C23: 700 | D23: 244105 | F23: 140370 | G23: 28320 | H23: 356855 | I23: 356855 | J23: 1021 | K23: 216916107 | P23: =IF('[1]2026 január'!B$21=0, "", '[1]2026 január'!B$21 ) -> 385175 | Q23: =IF(OR('[1]2026 január'!G21=0, ISBLANK('[1]2026 január'!G21)), "", '[1]2026 január'!G21 ) | R23: ='[1]2026 január'!W21 -> 0 | V23: =IF('[1]2026 január'!S21=0, "", '[1]2026 január'!S21 ) -> 124620 | W23: =IF('[1]2026 január'!T21=0, "", '[1]2026 január'!T21 ) -> 28320 | X23: =IF('[1]2026 január'!U21=0, "", '[1]2026 január'!U21 ) | Y23: =IF('[1]2026 január'!V21=0, "", '[1]2026 január'!V21 ) | Z23: =IF('[1]2026 január'!W21=0, "", '[1]2026 január'!W21 ) | AA23: =IF('[1]2026 január'!X21=0, "", '[1]2026 január'!X21 ) | AB23: =IF('[1]2026 január'!Y21=0, "", '[1]2026 január'!Y21 ) -> 152940 | AC23: =IF('[1]2026 január'!Z21=0, "", '[1]2026 január'!Z21 ) | AD23: =IF('[1]2026 január'!AA21=0, "", '[1]2026 január'!AA21 ) | AE23: =IF('[1]2026 január'!AB$21=0, "", '[1]2026 január'!AB$21 ) | AF23: =IF('[1]2026 január'!AC$21=0, "", '[1]2026 január'!AC$21 ) | AG23: =IF('[1]2026 január'!AD$21=0, "", '[1]2026 január'!AD$21 ) | AH23: =IF('[1]2026 január'!AE21=0, "", '[1]2026 január'!AE21 ) | AI23: =IF('[1]2026 január'!AF21=0, "", '[1]2026 január'!AF21 ) | AJ23: =IF('[1]2026 január'!AG21=0, "", '[1]2026 január'!AG21 ) | AK23: =IF('[1]2026 január'!AH21=0, "", '[1]2026 január'!AH21 )
A24: 46043 | B24: 305995 | C24: 1250 | D24: 158570 | F24: 133445 | G24: 25800 | H24: 267465 | I24: 267465 | J24: 1022 | K24: 217209372 | P24: =IF('[1]2026 január'!B$22=0, "", '[1]2026 január'!B$22 ) -> 293265 | Q24: =IF(OR('[1]2026 január'!G22=0, ISBLANK('[1]2026 január'!G22)), "", '[1]2026 január'!G22 ) | R24: ='[1]2026 január'!W22 -> 0 | V24: =IF('[1]2026 január'!S22=0, "", '[1]2026 január'!S22 ) -> 152940 | W24: =IF('[1]2026 január'!T22=0, "", '[1]2026 január'!T22 ) -> 25800 | X24: =IF('[1]2026 január'!U22=0, "", '[1]2026 január'!U22 ) | Y24: =IF('[1]2026 január'!V22=0, "", '[1]2026 január'!V22 ) | Z24: =IF('[1]2026 január'!W22=0, "", '[1]2026 január'!W22 ) | AA24: =IF('[1]2026 január'!X22=0, "", '[1]2026 január'!X22 ) | AB24: =IF('[1]2026 január'!Y22=0, "", '[1]2026 január'!Y22 ) -> 178740 | AC24: =IF('[1]2026 január'!Z22=0, "", '[1]2026 január'!Z22 ) | AD24: =IF('[1]2026 január'!AA22=0, "", '[1]2026 január'!AA22 ) | AE24: =IF('[1]2026 január'!AB$22=0, "", '[1]2026 január'!AB$22 ) | AF24: =IF('[1]2026 január'!AC$22=0, "", '[1]2026 január'!AC$22 ) | AG24: =IF('[1]2026 január'!AD$22=0, "", '[1]2026 január'!AD$22 ) | AH24: =IF('[1]2026 január'!AE22=0, "", '[1]2026 január'!AE22 ) | AI24: =IF('[1]2026 január'!AF22=0, "", '[1]2026 január'!AF22 ) | AJ24: =IF('[1]2026 január'!AG22=0, "", '[1]2026 január'!AG22 ) | AK24: =IF('[1]2026 január'!AH22=0, "", '[1]2026 január'!AH22 )
A25: 46044 | B25: 387015 | C25: 900 | D25: 201465 | F25: 158810 | G25: 26950 | H25: 334255 | I25: 334255 | J25: 1023 | K25: 217570547 | P25: =IF('[1]2026 január'!B$23=0, "", '[1]2026 január'!B$23 ) -> 361175 | Q25: =IF(OR('[1]2026 január'!G23=0, ISBLANK('[1]2026 január'!G23)), "", '[1]2026 január'!G23 ) | R25: ='[1]2026 január'!W23 -> 0 | V25: =IF('[1]2026 január'!S23=0, "", '[1]2026 január'!S23 ) -> 178740 | W25: =IF('[1]2026 január'!T23=0, "", '[1]2026 január'!T23 ) -> 26950 | X25: =IF('[1]2026 január'!U23=0, "", '[1]2026 január'!U23 ) | Y25: =IF('[1]2026 január'!V23=0, "", '[1]2026 január'!V23 ) | Z25: =IF('[1]2026 január'!W23=0, "", '[1]2026 január'!W23 ) | AA25: =IF('[1]2026 január'!X23=0, "", '[1]2026 január'!X23 ) | AB25: =IF('[1]2026 január'!Y23=0, "", '[1]2026 január'!Y23 ) -> 205690 | AC25: =IF('[1]2026 január'!Z23=0, "", '[1]2026 január'!Z23 ) | AD25: =IF('[1]2026 január'!AA23=0, "", '[1]2026 január'!AA23 ) | AE25: =IF('[1]2026 január'!AB$23=0, "", '[1]2026 január'!AB$23 ) | AF25: =IF('[1]2026 január'!AC$23=0, "", '[1]2026 január'!AC$23 ) | AG25: =IF('[1]2026 január'!AD$23=0, "", '[1]2026 január'!AD$23 ) | AH25: =IF('[1]2026 január'!AE23=0, "", '[1]2026 január'!AE23 ) | AI25: =IF('[1]2026 január'!AF23=0, "", '[1]2026 január'!AF23 ) | AJ25: =IF('[1]2026 január'!AG23=0, "", '[1]2026 január'!AG23 ) | AK25: =IF('[1]2026 január'!AH23=0, "", '[1]2026 január'!AH23 )
A26: 46045 | B26: 309170 | C26: 750 | D26: 194725 | F26: 97045 | G26: 8790 | H26: 283730 | I26: 283730 | J26: 1024 | K26: 217863067 | P26: =IF('[1]2026 január'!B$24=0, "", '[1]2026 január'!B$24 ) -> 292520 | Q26: =IF(OR('[1]2026 január'!G24=0, ISBLANK('[1]2026 január'!G24)), "", '[1]2026 január'!G24 ) | R26: ='[1]2026 január'!W24 -> 0 | V26: =IF('[1]2026 január'!S24=0, "", '[1]2026 január'!S24 ) -> 205690 | W26: =IF('[1]2026 január'!T24=0, "", '[1]2026 január'!T24 ) -> 8790 | X26: =IF('[1]2026 január'!U24=0, "", '[1]2026 január'!U24 ) | Y26: =IF('[1]2026 január'!V24=0, "", '[1]2026 január'!V24 ) -> 64015 | Z26: =IF('[1]2026 január'!W24=0, "", '[1]2026 január'!W24 ) | AA26: =IF('[1]2026 január'!X24=0, "", '[1]2026 január'!X24 ) | AB26: =IF('[1]2026 január'!Y24=0, "", '[1]2026 január'!Y24 ) -> 150465 | AC26: =IF('[1]2026 január'!Z24=0, "", '[1]2026 január'!Z24 ) | AD26: =IF('[1]2026 január'!AA24=0, "", '[1]2026 január'!AA24 ) -> Melinda | AE26: =IF('[1]2026 január'!AB$24=0, "", '[1]2026 január'!AB$24 ) | AF26: =IF('[1]2026 január'!AC$24=0, "", '[1]2026 január'!AC$24 ) | AG26: =IF('[1]2026 január'!AD$24=0, "", '[1]2026 január'!AD$24 ) | AH26: =IF('[1]2026 január'!AE24=0, "", '[1]2026 január'!AE24 ) | AI26: =IF('[1]2026 január'!AF24=0, "", '[1]2026 január'!AF24 ) | AJ26: =IF('[1]2026 január'!AG24=0, "", '[1]2026 január'!AG24 ) | AK26: =IF('[1]2026 január'!AH24=0, "", '[1]2026 január'!AH24 )
A27: 46046 | P27: =IF('[1]2026 január'!B$25=0, "", '[1]2026 január'!B$25 ) | Q27: =IF(OR('[1]2026 január'!G25=0, ISBLANK('[1]2026 január'!G25)), "", '[1]2026 január'!G25 ) | R27: ='[1]2026 január'!W25 -> 0 | V27: =IF('[1]2026 január'!S25=0, "", '[1]2026 január'!S25 ) -> 150465 | W27: =IF('[1]2026 január'!T25=0, "", '[1]2026 január'!T25 ) | X27: =IF('[1]2026 január'!U25=0, "", '[1]2026 január'!U25 ) | Y27: =IF('[1]2026 január'!V25=0, "", '[1]2026 január'!V25 ) | Z27: =IF('[1]2026 január'!W25=0, "", '[1]2026 január'!W25 ) | AA27: =IF('[1]2026 január'!X25=0, "", '[1]2026 január'!X25 ) | AB27: =IF('[1]2026 január'!Y25=0, "", '[1]2026 január'!Y25 ) -> 150465 | AC27: =IF('[1]2026 január'!Z25=0, "", '[1]2026 január'!Z25 ) | AD27: =IF('[1]2026 január'!AA25=0, "", '[1]2026 január'!AA25 ) | AE27: =IF('[1]2026 január'!AB$25=0, "", '[1]2026 január'!AB$25 ) | AF27: =IF('[1]2026 január'!AC$25=0, "", '[1]2026 január'!AC$25 ) | AG27: =IF('[1]2026 január'!AD$25=0, "", '[1]2026 január'!AD$25 ) | AH27: =IF('[1]2026 január'!AE25=0, "", '[1]2026 január'!AE25 ) | AI27: =IF('[1]2026 január'!AF25=0, "", '[1]2026 január'!AF25 ) | AJ27: =IF('[1]2026 január'!AG25=0, "", '[1]2026 január'!AG25 ) | AK27: =IF('[1]2026 január'!AH25=0, "", '[1]2026 január'!AH25 )
A28: 46047 | P28: =IF('[1]2026 január'!B$26=0, "", '[1]2026 január'!B$26 ) | Q28: =IF(OR('[1]2026 január'!G26=0, ISBLANK('[1]2026 január'!G26)), "", '[1]2026 január'!G26 ) | R28: ='[1]2026 január'!W26 -> 0 | V28: =IF('[1]2026 január'!S26=0, "", '[1]2026 január'!S26 ) -> 150465 | W28: =IF('[1]2026 január'!T26=0, "", '[1]2026 január'!T26 ) | X28: =IF('[1]2026 január'!U26=0, "", '[1]2026 január'!U26 ) | Y28: =IF('[1]2026 január'!V26=0, "", '[1]2026 január'!V26 ) | Z28: =IF('[1]2026 január'!W26=0, "", '[1]2026 január'!W26 ) | AA28: =IF('[1]2026 január'!X26=0, "", '[1]2026 január'!X26 ) | AB28: =IF('[1]2026 január'!Y26=0, "", '[1]2026 január'!Y26 ) -> 150465 | AC28: =IF('[1]2026 január'!Z26=0, "", '[1]2026 január'!Z26 ) | AD28: =IF('[1]2026 január'!AA26=0, "", '[1]2026 január'!AA26 ) | AE28: =IF('[1]2026 január'!AB$26=0, "", '[1]2026 január'!AB$26 ) | AF28: =IF('[1]2026 január'!AC$26=0, "", '[1]2026 január'!AC$26 ) | AG28: =IF('[1]2026 január'!AD$26=0, "", '[1]2026 január'!AD$26 ) | AH28: =IF('[1]2026 január'!AE26=0, "", '[1]2026 január'!AE26 ) | AI28: =IF('[1]2026 január'!AF26=0, "", '[1]2026 január'!AF26 ) | AJ28: =IF('[1]2026 január'!AG26=0, "", '[1]2026 január'!AG26 ) | AK28: =IF('[1]2026 január'!AH26=0, "", '[1]2026 január'!AH26 )
A29: 46048 | B29: 304025 | C29: 850 | D29: 170825 | F29: 124060 | G29: 20560 | H29: 272830 | I29: 272830 | J29: 1025 | K29: 218158802 | M29: 2340 | P29: =IF('[1]2026 január'!B$27=0, "", '[1]2026 január'!B$27 ) -> 293395 | Q29: =IF(OR('[1]2026 január'!G27=0, ISBLANK('[1]2026 január'!G27)), "", '[1]2026 január'!G27 ) | R29: ='[1]2026 január'!W27 -> 0 | V29: =IF('[1]2026 január'!S27=0, "", '[1]2026 január'!S27 ) -> 150465 | W29: =IF('[1]2026 január'!T27=0, "", '[1]2026 január'!T27 ) -> 20565 | X29: =IF('[1]2026 január'!U27=0, "", '[1]2026 január'!U27 ) | Y29: =IF('[1]2026 január'!V27=0, "", '[1]2026 január'!V27 ) | Z29: =IF('[1]2026 január'!W27=0, "", '[1]2026 január'!W27 ) | AA29: =IF('[1]2026 január'!X27=0, "", '[1]2026 január'!X27 ) | AB29: =IF('[1]2026 január'!Y27=0, "", '[1]2026 január'!Y27 ) -> 171030 | AC29: =IF('[1]2026 január'!Z27=0, "", '[1]2026 január'!Z27 ) | AD29: =IF('[1]2026 január'!AA27=0, "", '[1]2026 január'!AA27 ) | AE29: =IF('[1]2026 január'!AB$27=0, "", '[1]2026 január'!AB$27 ) | AF29: =IF('[1]2026 január'!AC$27=0, "", '[1]2026 január'!AC$27 ) | AG29: =IF('[1]2026 január'!AD$27=0, "", '[1]2026 január'!AD$27 ) | AH29: =IF('[1]2026 január'!AE27=0, "", '[1]2026 január'!AE27 ) | AI29: =IF('[1]2026 január'!AF27=0, "", '[1]2026 január'!AF27 ) | AJ29: =IF('[1]2026 január'!AG27=0, "", '[1]2026 január'!AG27 ) | AK29: =IF('[1]2026 január'!AH27=0, "", '[1]2026 január'!AH27 )
A30: 46049 | B30: 362210 | C30: 800 | D30: 214315 | F30: 135480 | G30: 26430 | H30: 324165 | I30: 324165 | J30: 1026 | K30: 218509397 | P30: =IF('[1]2026 január'!B$28=0, "", '[1]2026 január'!B$28 ) -> 350595 | Q30: =IF(OR('[1]2026 január'!G28=0, ISBLANK('[1]2026 január'!G28)), "", '[1]2026 január'!G28 ) | R30: ='[1]2026 január'!W28 -> 0 | V30: =IF('[1]2026 január'!S28=0, "", '[1]2026 január'!S28 ) -> 171030 | W30: =IF('[1]2026 január'!T28=0, "", '[1]2026 január'!T28 ) -> 26430 | X30: =IF('[1]2026 január'!U28=0, "", '[1]2026 január'!U28 ) | Y30: =IF('[1]2026 január'!V28=0, "", '[1]2026 január'!V28 ) | Z30: =IF('[1]2026 január'!W28=0, "", '[1]2026 január'!W28 ) | AA30: =IF('[1]2026 január'!X28=0, "", '[1]2026 január'!X28 ) | AB30: =IF('[1]2026 január'!Y28=0, "", '[1]2026 január'!Y28 ) -> 197460 | AC30: =IF('[1]2026 január'!Z28=0, "", '[1]2026 január'!Z28 ) | AD30: =IF('[1]2026 január'!AA28=0, "", '[1]2026 január'!AA28 ) | AE30: =IF('[1]2026 január'!AB$28=0, "", '[1]2026 január'!AB$28 ) | AF30: =IF('[1]2026 január'!AC$28=0, "", '[1]2026 január'!AC$28 ) | AG30: =IF('[1]2026 január'!AD$28=0, "", '[1]2026 január'!AD$28 ) | AH30: =IF('[1]2026 január'!AE28=0, "", '[1]2026 január'!AE28 ) | AI30: =IF('[1]2026 január'!AF28=0, "", '[1]2026 január'!AF28 ) | AJ30: =IF('[1]2026 január'!AG28=0, "", '[1]2026 január'!AG28 ) | AK30: =IF('[1]2026 január'!AH28=0, "", '[1]2026 január'!AH28 )
A31: 46050 | B31: 321215 | C31: 1050 | D31: 159435 | F31: 150590 | G31: 27800 | H31: 283275 | I31: 283275 | J31: 1027 | K31: 218820478 | P31: =IF('[1]2026 január'!B$29=0, "", '[1]2026 január'!B$29 ) -> 311075 | Q31: =IF(OR('[1]2026 január'!G29=0, ISBLANK('[1]2026 január'!G29)), "", '[1]2026 január'!G29 ) | R31: ='[1]2026 január'!W29 -> 0 | V31: =IF('[1]2026 január'!S29=0, "", '[1]2026 január'!S29 ) -> 197460 | W31: =IF('[1]2026 január'!T29=0, "", '[1]2026 január'!T29 ) -> 27800 | X31: =IF('[1]2026 január'!U29=0, "", '[1]2026 január'!U29 ) | Y31: =IF('[1]2026 január'!V29=0, "", '[1]2026 január'!V29 ) | Z31: =IF('[1]2026 január'!W29=0, "", '[1]2026 január'!W29 ) | AA31: =IF('[1]2026 január'!X29=0, "", '[1]2026 január'!X29 ) | AB31: =IF('[1]2026 január'!Y29=0, "", '[1]2026 január'!Y29 ) -> 225260 | AC31: =IF('[1]2026 január'!Z29=0, "", '[1]2026 január'!Z29 ) | AD31: =IF('[1]2026 január'!AA29=0, "", '[1]2026 január'!AA29 ) | AE31: =IF('[1]2026 január'!AB$29=0, "", '[1]2026 január'!AB$29 ) | AF31: =IF('[1]2026 január'!AC$29=0, "", '[1]2026 január'!AC$29 ) | AG31: =IF('[1]2026 január'!AD$29=0, "", '[1]2026 január'!AD$29 ) | AH31: =IF('[1]2026 január'!AE29=0, "", '[1]2026 január'!AE29 ) | AI31: =IF('[1]2026 január'!AF29=0, "", '[1]2026 január'!AF29 ) | AJ31: =IF('[1]2026 január'!AG29=0, "", '[1]2026 január'!AG29 ) | AK31: =IF('[1]2026 január'!AH29=0, "", '[1]2026 január'!AH29 )
A32: 46051 | B32: 350505 | C32: 950 | D32: 234076 | F32: 142204 | G32: 26835 | H32: 348405 | I32: 348405 | J32: 1028 | K32: 219197702 | M32: 1990 | P32: =IF('[1]2026 január'!B$30=0, "", '[1]2026 január'!B$30 ) -> 335240 | Q32: =IF(OR('[1]2026 január'!G30=0, ISBLANK('[1]2026 január'!G30)), "", '[1]2026 január'!G30 ) | R32: ='[1]2026 január'!W30 -> 0 | V32: =IF('[1]2026 január'!S30=0, "", '[1]2026 január'!S30 ) -> 225260 | W32: =IF('[1]2026 január'!T30=0, "", '[1]2026 január'!T30 ) -> -13165 | X32: =IF('[1]2026 január'!U30=0, "", '[1]2026 január'!U30 ) -> 40000 | Y32: =IF('[1]2026 január'!V30=0, "", '[1]2026 január'!V30 ) | Z32: =IF('[1]2026 január'!W30=0, "", '[1]2026 január'!W30 ) | AA32: =IF('[1]2026 január'!X30=0, "", '[1]2026 január'!X30 ) | AB32: =IF('[1]2026 január'!Y30=0, "", '[1]2026 január'!Y30 ) -> 252095 | AC32: =IF('[1]2026 január'!Z30=0, "", '[1]2026 január'!Z30 ) | AD32: =IF('[1]2026 január'!AA30=0, "", '[1]2026 január'!AA30 ) -> Vip töltés | AE32: =IF('[1]2026 január'!AB$30=0, "", '[1]2026 január'!AB$30 ) | AF32: =IF('[1]2026 január'!AC$30=0, "", '[1]2026 január'!AC$30 ) | AG32: =IF('[1]2026 január'!AD$30=0, "", '[1]2026 január'!AD$30 ) | AH32: =IF('[1]2026 január'!AE30=0, "", '[1]2026 január'!AE30 ) | AI32: =IF('[1]2026 január'!AF30=0, "", '[1]2026 január'!AF30 ) | AJ32: =IF('[1]2026 január'!AG30=0, "", '[1]2026 január'!AG30 ) | AK32: =IF('[1]2026 január'!AH30=0, "", '[1]2026 január'!AH30 )
A33: 46052 | B33: 330590 | C33: 750 | D33: 217820 | F33: 100025 | G33: 16220 | H33: 302375 | I33: 302375 | J33: 1029 | K33: 219516297 | P33: =IF('[1]2026 január'!B$31=0, "", '[1]2026 január'!B$31 ) -> 318595 | Q33: =IF(OR('[1]2026 január'!G31=0, ISBLANK('[1]2026 január'!G31)), "", '[1]2026 január'!G31 ) | R33: ='[1]2026 január'!W31 -> 0 | V33: =IF('[1]2026 január'!S31=0, "", '[1]2026 január'!S31 ) -> 252095 | W33: =IF('[1]2026 január'!T31=0, "", '[1]2026 január'!T31 ) -> 16220 | X33: =IF('[1]2026 január'!U31=0, "", '[1]2026 január'!U31 ) | Y33: =IF('[1]2026 január'!V31=0, "", '[1]2026 január'!V31 ) -> 64015 | Z33: =IF('[1]2026 január'!W31=0, "", '[1]2026 január'!W31 ) | AA33: =IF('[1]2026 január'!X31=0, "", '[1]2026 január'!X31 ) | AB33: =IF('[1]2026 január'!Y31=0, "", '[1]2026 január'!Y31 ) -> 204300 | AC33: =IF('[1]2026 január'!Z31=0, "", '[1]2026 január'!Z31 ) | AD33: =IF('[1]2026 január'!AA31=0, "", '[1]2026 január'!AA31 ) -> Melinda | AE33: =IF('[1]2026 január'!AB$31=0, "", '[1]2026 január'!AB$31 ) | AF33: =IF('[1]2026 január'!AC$31=0, "", '[1]2026 január'!AC$31 ) | AG33: =IF('[1]2026 január'!AD$31=0, "", '[1]2026 január'!AD$31 ) | AH33: =IF('[1]2026 január'!AE31=0, "", '[1]2026 január'!AE31 ) | AI33: =IF('[1]2026 január'!AF31=0, "", '[1]2026 január'!AF31 ) | AJ33: =IF('[1]2026 január'!AG31=0, "", '[1]2026 január'!AG31 ) | AK33: =IF('[1]2026 január'!AH31=0, "", '[1]2026 január'!AH31 )
A34: 46053 | P34: =IF('[1]2026 január'!B$32=0, "", '[1]2026 január'!B$32 ) | Q34: =IF(OR('[1]2026 január'!G32=0, ISBLANK('[1]2026 január'!G32)), "", '[1]2026 január'!G32 ) | R34: ='[1]2026 január'!W32 -> 0 | V34: =IF('[1]2026 január'!S32=0, "", '[1]2026 január'!S32 ) -> 204300 | W34: =IF('[1]2026 január'!T32=0, "", '[1]2026 január'!T32 ) | X34: =IF('[1]2026 január'!U32=0, "", '[1]2026 január'!U32 ) | Y34: =IF('[1]2026 január'!V32=0, "", '[1]2026 január'!V32 ) | Z34: =IF('[1]2026 január'!W32=0, "", '[1]2026 január'!W32 ) | AA34: =IF('[1]2026 január'!X32=0, "", '[1]2026 január'!X32 ) | AB34: =IF('[1]2026 január'!Y32=0, "", '[1]2026 január'!Y32 ) -> 204300 | AC34: =IF('[1]2026 január'!Z32=0, "", '[1]2026 január'!Z32 ) | AD34: =IF('[1]2026 január'!AA32=0, "", '[1]2026 január'!AA32 ) | AE34: =IF('[1]2026 január'!AB$32=0, "", '[1]2026 január'!AB$32 ) | AF34: =IF('[1]2026 január'!AC$32=0, "", '[1]2026 január'!AC$32 ) | AG34: =IF('[1]2026 január'!AD$32=0, "", '[1]2026 január'!AD$32 ) | AH34: =IF('[1]2026 január'!AE32=0, "", '[1]2026 január'!AE32 ) | AI34: =IF('[1]2026 január'!AF32=0, "", '[1]2026 január'!AF32 ) | AJ34: =IF('[1]2026 január'!AG32=0, "", '[1]2026 január'!AG32 ) | AK34: =IF('[1]2026 január'!AH32=0, "", '[1]2026 január'!AH32 )
A35: Összesen: | C35: =SUM(C1:C34) -> 17250 | D35: =SUM(D1:D34) -> 4328426 | E35: =SUM(E1:E34) -> 0.18 | F35: =SUM(F1:F34) -> 2825575.3 | G35: =SUM(G1:G34) -> 459515 | H35: =SUM(H3:H34) -> 6705640 | I35: =SUM(I3:I34) -> 6746640 | K35: 219216297 | L35: 7171251 | P35: =IF('[1]2026 január'!B$33=0, "", '[1]2026 január'!B$33 ) -> 6975130 | Q35: =IF(OR('[1]2026 január'!G33=0, ISBLANK('[1]2026 január'!G33)), "", '[1]2026 január'!G33 ) | R35: ='[1]2026 január'!W33 -> 0 | V35: =IF('[1]2026 január'!S33=0, "", '[1]2026 január'!S33 ) | W35: =IF('[1]2026 január'!T33=0, "", '[1]2026 január'!T33 ) -> 228420 | X35: =IF('[1]2026 január'!U33=0, "", '[1]2026 január'!U33 ) -> 259985 | Y35: =IF('[1]2026 január'!V33=0, "", '[1]2026 január'!V33 ) | Z35: =IF('[1]2026 január'!W33=0, "", '[1]2026 január'!W33 ) | AA35: =IF('[1]2026 január'!X33=0, "", '[1]2026 január'!X33 ) | AB35: =IF('[1]2026 január'!Y33=0, "", '[1]2026 január'!Y33 ) | AC35: =IF('[1]2026 január'!Z33=0, "", '[1]2026 január'!Z33 ) | AD35: =IF('[1]2026 január'!AA33=0, "", '[1]2026 január'!AA33 ) | AE35: =IF('[1]2026 január'!AB$33=0, "", '[1]2026 január'!AB$33 ) | AF35: =IF('[1]2026 január'!AC$33=0, "", '[1]2026 január'!AC$33 ) | AG35: =IF('[1]2026 január'!AD$33=0, "", '[1]2026 január'!AD$33 ) | AH35: =IF('[1]2026 január'!AE33=0, "", '[1]2026 január'!AE33 ) | AI35: =IF('[1]2026 január'!AF33=0, "", '[1]2026 január'!AF33 ) | AJ35: =IF('[1]2026 január'!AG33=0, "", '[1]2026 január'!AG33 ) | AK35: =IF('[1]2026 január'!AH33=0, "", '[1]2026 január'!AH33 )
C36: =C35+D35+E35+F35 -> 7171251.5 | G36: =G35+H35 -> 7165155
A40: ÜZENŐFAL
A44: Február | P44: ='[1]2026 január'!B42 -> 0 | Q44: ='[1]2026 január'!G42 -> 0 | R44: ='[1]2026 január'!W42 -> 0 | S44: Eredmény | V44: ='[1]2026 január'!S42 -> 0 | W44: ='[1]2026 január'!T42 -> 0 | X44: ='[1]2026 január'!U42 -> 0 | Y44: ='[1]2026 január'!V42 -> 0 | Z44: ='[1]2026 január'!W42 -> 0 | AA44: ='[1]2026 január'!X42 -> 0 | AB44: ='[1]2026 január'!Y42 -> 0 | AC44: ='[1]2026 január'!Z42 -> 0 | ... AG44: ='[1]2026 január'!AD42 -> 0
A45: 46054 | Q45: =IF(OR('[1]2026 február'!G43=0, ISBLANK('[1]2026 február'!G43)), "", '[1]2026 február'!G43 ) | R45: ='[1]2026 február'!W43 -> 0 | S45: =P46-Q45-R45-G45-H45 -> #VALUE! | V45: =IF('[1]2026 február'!S43=0, "", '[1]2026 február'!S43 ) | W45: =IF('[1]2026 február'!T43=0, "", '[1]2026 február'!T43 ) | X45: =IF('[1]2026 február'!U43=0, "", '[1]2026 február'!U43 ) | Y45: =IF('[1]2026 február'!V43=0, "", '[1]2026 február'!V43 ) | Z45: =IF('[1]2026 február'!W43=0, "", '[1]2026 február'!W43 ) | AA45: =IF('[1]2026 február'!X43=0, "", '[1]2026 február'!X43 ) | AB45: =IF('[1]2026 február'!Y43=0, "", '[1]2026 február'!Y43 ) | AC45: =IF('[1]2026 február'!Z43=0, "", '[1]2026 február'!Z43 ) | AD45: =IF('[1]2026 február'!AA43=0, "", '[1]2026 február'!AA43 ) | AE45: =IF('[1]2026 február'!AB$2=0, "", '[1]2026 február'!AB$2 ) | AF45: =IF('[1]2026 február'!AC$2=0, "", '[1]2026 február'!AC$2 ) | AG45: =IF('[1]2026 február'!AD$2=0, "", '[1]2026 február'!AD$2 ) | AH45: =IF('[1]2026 február'!AE43=0, "", '[1]2026 február'!AE43 ) | AI45: =IF('[1]2026 február'!AF43=0, "", '[1]2026 február'!AF43 ) | AJ45: =IF('[1]2026 február'!AG43=0, "", '[1]2026 február'!AG43 ) | AK45: =IF('[1]2026 február'!AH43=0, "", '[1]2026 február'!AH43 )
A46: 46055 | B46: 335525 | C46: 1350 | D46: 299592 | E46: 1750 | F46: 16480 | G46: 28090 | H46: 291082 | I46: 291082 | J46: 1030 | K46: 219835469 | P46: =IF('[1]2026 február'!B$2=0, "", '[1]2026 február'!B$2 ) -> 319570 | Q46: =IF(OR('[1]2026 február'!G44=0, ISBLANK('[1]2026 február'!G44)), "", '[1]2026 február'!G44 ) | R46: ='[1]2026 február'!W44 -> 0 | V46: =IF('[1]2026 február'!S44=0, "", '[1]2026 február'!S44 ) | W46: =IF('[1]2026 február'!T44=0, "", '[1]2026 február'!T44 ) | X46: =IF('[1]2026 február'!U44=0, "", '[1]2026 február'!U44 ) | Y46: =IF('[1]2026 február'!V44=0, "", '[1]2026 február'!V44 ) | Z46: =IF('[1]2026 február'!W44=0, "", '[1]2026 február'!W44 ) | AA46: =IF('[1]2026 február'!X44=0, "", '[1]2026 február'!X44 ) | AB46: =IF('[1]2026 február'!Y44=0, "", '[1]2026 február'!Y44 ) | AC46: =IF('[1]2026 február'!Z44=0, "", '[1]2026 február'!Z44 ) | AD46: =IF('[1]2026 február'!AA44=0, "", '[1]2026 február'!AA44 ) | AE46: =IF('[1]2026 február'!AB$3=0, "", '[1]2026 február'!AB$3 ) | AF46: =IF('[1]2026 február'!AC$3=0, "", '[1]2026 február'!AC$3 ) | AG46: =IF('[1]2026 február'!AD$3=0, "", '[1]2026 február'!AD$3 ) | AH46: =IF('[1]2026 február'!AE44=0, "", '[1]2026 február'!AE44 ) | AI46: =IF('[1]2026 február'!AF44=0, "", '[1]2026 február'!AF44 ) | AJ46: =IF('[1]2026 február'!AG44=0, "", '[1]2026 február'!AG44 ) | AK46: =IF('[1]2026 február'!AH44=0, "", '[1]2026 február'!AH44 )
...

Sheet Knorr105
A1: AP A09111376 | B1: Novohost | C1: 0 | D1: 0.05 | E1: 0.18 | F1: 0.27 | G1: készpénz | H1: kártya | I1: terminál sz. bankkártya | J1: Borravaló | K1: zárás ssz | L1: göngyölt e. | M1: időszaki össz: | N1: EUR | O1: jegyzőkönyv | Q1: AP A24010154 | R1: Novohost | S1: 0 | T1: 0.05 | U1: 0.18 | V1: 0.27 | W1: készpénz | X1: kártya | Y1: terminál sz. bankkártya | Z1: Borravaló | AA1: zárás ssz | AB1: göngyölt e. | AC1: időszaki össz: | AD1: EUR | AE1: jegyzőkönyv | AG1: AP A13609805 | AH1: Novohost | AI1: 0 | AJ1: 0.05 | AK1: 0.18 | AL1: 0.27 | AM1: készpénz | AN1: kártya | AO1: terminál sz. bankkártya | AP1: Borravaló | AQ1: zárás ssz | AR1: göngyölt e. | AS1: időszaki össz: | AT1: EUR | AU1: AP A24004860 | AV1: 0 | AW1: 0 | AX1: 0 | AY1: 0 | AZ1: 0 | BA1: 0 | BB1: terminál sz. bankkártya | BC1: 0 | BD1: 0 | BE1: időszaki össz: | BG1: jegyzőkönyv | BI1: AP A09110892 | BJ1: Novohost | BK1: 0 | BL1: 0.05 | BM1: 0.18 | BN1: 0.27 | BO1: készpénz | BP1: kártya | BQ1: terminál sz. bankkártya | BR1: Borravaló | BS1: zárás sz. | BT1: göngyölt | BU1: időszaki össz: | BV1: EUR | BW1: jegyzőkönyv | BY1: ='[2]2026 január'!B$1 -> Novohost
A2: Január | Q2: Január | AG2: Január | AU2: Január | BI2: Január | BY2: ='[2]2026 január'!B$1 -> Novohost | BZ2: ='[2]2026 január'!G1 -> Tartalék Kiadás | CA2: ='[2]2026 január'!W1 -> Kivét | CB2: Eredmény | CE2: ='[2]2026 január'!S1 -> Pénztár nyitó | CF2: ='[2]2026 január'!T1 -> Pénztár kp bevétel | CG2: ='[2]2026 január'!U1 -> Egyéb bevétel | CH2: ='[2]2026 január'!V1 -> Költött | CI2: ='[2]2026 január'!W1 -> Kivét | CJ2: ='[2]2026 január'!X1 -> Eltérés | CK2: ='[2]2026 január'!Y1 -> Záró | CL2: ='[2]2026 január'!Z1 -> Megjegyzések | ... CP2: ='[2]2026 január'!AD1 -> Egyéb kiadás
A3: 46023 | Q3: 46023 | AG3: 46023 | AU3: 45658 | BI3: 46023 | BY3: =IF('[2]2026 január'!B$2=0, "", '[2]2026 január'!B$2 ) | BZ3: =IF(OR('[2]2026 január'!G2=0, ISBLANK('[2]2026 január'!G2)), "", '[2]2026 január'!G2 ) | CA3: ='[2]2026 január'!W2 -> 0 | CB3: =P3-Q3-S3-G3-H3 -> -46023 | CE3: =IF('[2]2026 január'!S2=0, "", '[2]2026 január'!S2 ) | CF3: =IF('[2]2026 január'!T2=0, "", '[2]2026 január'!T2 ) | CG3: =IF('[2]2026 január'!U2=0, "", '[2]2026 január'!U2 ) | CH3: =IF('[2]2026 január'!V2=0, "", '[2]2026 január'!V2 ) | CI3: =IF('[2]2026 január'!W2=0, "", '[2]2026 január'!W2 ) | CJ3: =IF('[2]2026 január'!X2=0, "", '[2]2026 január'!X2 ) | CK3: =IF('[2]2026 január'!Y2=0, "", '[2]2026 január'!Y2 ) | CL3: =IF('[2]2026 január'!Z2=0, "", '[2]2026 január'!Z2 ) | ... CP3: =IF('[2]2026 január'!AD2=0, "", '[2]2026 január'!AD2 ) | CQ3: =IF('[2]2026 január'!AE$2=0, "", '[2]2026 január'!AE$2 ) | CR3: =IF('[2]2026 január'!AF2=0, "", '[2]2026 január'!AF2 ) | CS3: =IF('[2]2026 január'!AG2=0, "", '[2]2026 január'!AG2 ) | CT3: =IF('[2]2026 január'!AH2=0, "", '[2]2026 január'!AH2 )
